ply
format ascii 1.0
comment : MagicaVoxel @ Ephtracy
element vertex 156942
property float x
property float y
property float z
property uchar red
property uchar green
property uchar blue
end_header
19 -59 31 131 154 169
20 -59 31 131 154 169
21 -59 31 131 154 169
22 -59 31 131 154 169
23 -59 31 131 154 169
24 -59 31 131 154 169
25 -59 31 131 154 169
26 -59 31 131 154 169
27 -59 31 131 154 169
28 -59 31 131 154 169
29 -59 31 131 154 169
30 -59 31 131 154 169
31 -59 31 131 154 169
32 -59 31 131 154 169
33 -59 31 131 154 169
34 -59 31 131 154 169
35 -59 31 131 154 169
36 -59 31 131 154 169
37 -59 31 131 154 169
38 -59 31 131 154 169
39 -59 31 131 154 169
40 -59 31 131 154 169
41 -59 31 131 154 169
42 -59 31 131 154 169
43 -59 31 131 154 169
44 -59 31 131 154 169
45 -59 31 131 154 169
46 -59 31 131 154 169
47 -59 31 131 154 169
48 -59 31 131 154 169
49 -59 31 131 154 169
50 -59 31 131 154 169
19 -58 31 131 154 169
20 -58 31 131 154 169
21 -58 31 131 154 169
22 -58 31 131 154 169
23 -58 31 131 154 169
24 -58 31 131 154 169
25 -58 31 131 154 169
26 -58 31 131 154 169
27 -58 31 131 154 169
28 -58 31 131 154 169
29 -58 31 131 154 169
30 -58 31 131 154 169
31 -58 31 131 154 169
32 -58 31 131 154 169
33 -58 31 131 154 169
34 -58 31 131 154 169
35 -58 31 131 154 169
36 -58 31 131 154 169
37 -58 31 131 154 169
38 -58 31 131 154 169
39 -58 31 131 154 169
40 -58 31 131 154 169
41 -58 31 131 154 169
42 -58 31 131 154 169
43 -58 31 131 154 169
44 -58 31 131 154 169
45 -58 31 131 154 169
46 -58 31 131 154 169
47 -58 31 131 154 169
48 -58 31 131 154 169
49 -58 31 131 154 169
50 -58 31 131 154 169
19 -57 31 131 154 169
20 -57 31 131 154 169
21 -57 31 131 154 169
22 -57 31 131 154 169
23 -57 31 131 154 169
24 -57 31 131 154 169
25 -57 31 131 154 169
26 -57 31 131 154 169
27 -57 31 131 154 169
28 -57 31 131 154 169
29 -57 31 131 154 169
30 -57 31 131 154 169
31 -57 31 131 154 169
32 -57 31 131 154 169
33 -57 31 131 154 169
34 -57 31 131 154 169
35 -57 31 131 154 169
36 -57 31 131 154 169
37 -57 31 131 154 169
38 -57 31 131 154 169
39 -57 31 131 154 169
40 -57 31 131 154 169
41 -57 31 131 154 169
42 -57 31 131 154 169
43 -57 31 131 154 169
44 -57 31 131 154 169
45 -57 31 131 154 169
46 -57 31 131 154 169
47 -57 31 131 154 169
48 -57 31 131 154 169
49 -57 31 131 154 169
50 -57 31 131 154 169
19 -56 31 131 154 169
20 -56 31 120 141 153
21 -56 31 120 141 153
22 -56 31 131 154 169
23 -56 31 131 154 169
24 -56 31 120 141 153
25 -56 31 120 141 153
26 -56 31 131 154 169
27 -56 31 131 154 169
28 -56 31 120 141 153
29 -56 31 120 141 153
30 -56 31 131 154 169
31 -56 31 131 154 169
32 -56 31 120 141 153
33 -56 31 120 141 153
34 -56 31 131 154 169
35 -56 31 131 154 169
36 -56 31 120 141 153
37 -56 31 120 141 153
38 -56 31 131 154 169
39 -56 31 131 154 169
40 -56 31 120 141 153
41 -56 31 120 141 153
42 -56 31 131 154 169
43 -56 31 131 154 169
44 -56 31 120 141 153
45 -56 31 120 141 153
46 -56 31 131 154 169
47 -56 31 131 154 169
48 -56 31 120 141 153
49 -56 31 120 141 153
50 -56 31 131 154 169
19 -55 31 131 154 169
20 -55 31 120 141 153
21 -55 31 120 141 153
22 -55 31 131 154 169
23 -55 31 131 154 169
24 -55 31 120 141 153
25 -55 31 120 141 153
26 -55 31 131 154 169
27 -55 31 131 154 169
28 -55 31 120 141 153
29 -55 31 120 141 153
30 -55 31 131 154 169
31 -55 31 131 154 169
32 -55 31 120 141 153
33 -55 31 120 141 153
34 -55 31 131 154 169
35 -55 31 131 154 169
36 -55 31 120 141 153
37 -55 31 120 141 153
38 -55 31 131 154 169
39 -55 31 131 154 169
40 -55 31 120 141 153
41 -55 31 120 141 153
42 -55 31 131 154 169
43 -55 31 131 154 169
44 -55 31 120 141 153
45 -55 31 120 141 153
46 -55 31 131 154 169
47 -55 31 131 154 169
48 -55 31 120 141 153
49 -55 31 120 141 153
50 -55 31 131 154 169
19 -54 31 131 154 169
20 -54 31 120 141 153
21 -54 31 120 141 153
22 -54 31 131 154 169
23 -54 31 131 154 169
24 -54 31 120 141 153
25 -54 31 120 141 153
26 -54 31 131 154 169
27 -54 31 131 154 169
28 -54 31 120 141 153
29 -54 31 120 141 153
30 -54 31 131 154 169
31 -54 31 131 154 169
32 -54 31 120 141 153
33 -54 31 120 141 153
34 -54 31 131 154 169
35 -54 31 131 154 169
36 -54 31 120 141 153
37 -54 31 120 141 153
38 -54 31 131 154 169
39 -54 31 131 154 169
40 -54 31 120 141 153
41 -54 31 120 141 153
42 -54 31 131 154 169
43 -54 31 131 154 169
44 -54 31 120 141 153
45 -54 31 120 141 153
46 -54 31 131 154 169
47 -54 31 131 154 169
48 -54 31 120 141 153
49 -54 31 120 141 153
50 -54 31 131 154 169
19 -53 31 150 176 191
20 -53 31 150 176 191
21 -53 31 150 176 191
22 -53 31 150 176 191
23 -53 31 150 176 191
24 -53 31 150 176 191
25 -53 31 150 176 191
26 -53 31 150 176 191
27 -53 31 150 176 191
28 -53 31 150 176 191
29 -53 31 150 176 191
30 -53 31 150 176 191
31 -53 31 150 176 191
32 -53 31 150 176 191
33 -53 31 150 176 191
34 -53 31 150 176 191
35 -53 31 150 176 191
36 -53 31 150 176 191
37 -53 31 150 176 191
38 -53 31 150 176 191
39 -53 31 150 176 191
40 -53 31 150 176 191
41 -53 31 150 176 191
42 -53 31 150 176 191
43 -53 31 150 176 191
44 -53 31 150 176 191
45 -53 31 150 176 191
46 -53 31 150 176 191
47 -53 31 150 176 191
48 -53 31 150 176 191
49 -53 31 150 176 191
50 -53 31 150 176 191
19 -52 31 150 176 191
20 -52 31 150 176 191
21 -52 31 150 176 191
22 -52 31 150 176 191
23 -52 31 150 176 191
24 -52 31 150 176 191
25 -52 31 150 176 191
26 -52 31 150 176 191
27 -52 31 150 176 191
28 -52 31 150 176 191
29 -52 31 150 176 191
30 -52 31 150 176 191
31 -52 31 150 176 191
32 -52 31 150 176 191
33 -52 31 150 176 191
34 -52 31 150 176 191
35 -52 31 150 176 191
36 -52 31 150 176 191
37 -52 31 150 176 191
38 -52 31 150 176 191
39 -52 31 150 176 191
40 -52 31 150 176 191
41 -52 31 150 176 191
42 -52 31 150 176 191
43 -52 31 150 176 191
44 -52 31 150 176 191
45 -52 31 150 176 191
46 -52 31 150 176 191
47 -52 31 150 176 191
48 -52 31 150 176 191
49 -52 31 150 176 191
50 -52 31 150 176 191
43 -51 31 150 176 191
44 -51 31 150 176 191
45 -51 31 150 176 191
46 -51 31 150 176 191
47 -51 31 150 176 191
48 -51 31 150 176 191
49 -51 31 150 176 191
50 -51 31 150 176 191
43 -50 31 150 176 191
44 -50 31 150 176 191
45 -50 31 150 176 191
46 -50 31 150 176 191
47 -50 31 150 176 191
48 -50 31 150 176 191
49 -50 31 150 176 191
50 -50 31 150 176 191
43 -49 31 150 176 191
44 -49 31 150 176 191
45 -49 31 150 176 191
46 -49 31 150 176 191
47 -49 31 150 176 191
48 -49 31 150 176 191
49 -49 31 150 176 191
50 -49 31 150 176 191
43 -48 31 150 176 191
44 -48 31 150 176 191
45 -48 31 150 176 191
46 -48 31 150 176 191
47 -48 31 150 176 191
48 -48 31 150 176 191
49 -48 31 150 176 191
50 -48 31 150 176 191
43 -47 31 150 176 191
44 -47 31 150 176 191
45 -47 31 150 176 191
46 -47 31 150 176 191
47 -47 31 150 176 191
48 -47 31 150 176 191
49 -47 31 150 176 191
50 -47 31 150 176 191
43 -46 31 150 176 191
44 -46 31 150 176 191
45 -46 31 150 176 191
46 -46 31 150 176 191
47 -46 31 150 176 191
48 -46 31 150 176 191
49 -46 31 150 176 191
50 -46 31 150 176 191
43 -45 31 150 176 191
44 -45 31 150 176 191
45 -45 31 150 176 191
46 -45 31 150 176 191
47 -45 31 150 176 191
48 -45 31 150 176 191
49 -45 31 150 176 191
50 -45 31 150 176 191
43 -44 31 150 176 191
44 -44 31 150 176 191
45 -44 31 150 176 191
46 -44 31 150 176 191
47 -44 31 150 176 191
48 -44 31 150 176 191
49 -44 31 150 176 191
50 -44 31 150 176 191
19 -34 31 99 117 138
20 -34 31 99 117 138
21 -34 31 99 117 138
22 -34 31 99 117 138
23 -34 31 99 117 138
24 -34 31 99 117 138
25 -34 31 99 117 138
26 -34 31 99 117 138
27 -34 31 99 117 138
28 -34 31 99 117 138
29 -34 31 99 117 138
30 -34 31 99 117 138
31 -34 31 99 117 138
32 -34 31 99 117 138
33 -34 31 99 117 138
34 -34 31 99 117 138
35 -34 31 99 117 138
36 -34 31 99 117 138
37 -34 31 99 117 138
38 -34 31 99 117 138
39 -34 31 99 117 138
40 -34 31 99 117 138
41 -34 31 99 117 138
42 -34 31 99 117 138
19 -33 31 99 117 138
20 -33 31 99 117 138
21 -33 31 99 117 138
22 -33 31 99 117 138
23 -33 31 99 117 138
24 -33 31 99 117 138
25 -33 31 99 117 138
26 -33 31 99 117 138
27 -33 31 99 117 138
28 -33 31 99 117 138
29 -33 31 99 117 138
30 -33 31 99 117 138
31 -33 31 99 117 138
32 -33 31 99 117 138
33 -33 31 99 117 138
34 -33 31 99 117 138
35 -33 31 99 117 138
36 -33 31 99 117 138
37 -33 31 99 117 138
38 -33 31 99 117 138
39 -33 31 99 117 138
40 -33 31 99 117 138
41 -33 31 99 117 138
42 -33 31 99 117 138
19 -32 31 99 117 138
20 -32 31 99 117 138
21 -32 31 99 117 138
22 -32 31 99 117 138
23 -32 31 99 117 138
24 -32 31 99 117 138
25 -32 31 99 117 138
26 -32 31 99 117 138
27 -32 31 99 117 138
28 -32 31 99 117 138
29 -32 31 99 117 138
30 -32 31 99 117 138
31 -32 31 99 117 138
32 -32 31 99 117 138
33 -32 31 99 117 138
34 -32 31 99 117 138
35 -32 31 99 117 138
36 -32 31 99 117 138
37 -32 31 99 117 138
38 -32 31 99 117 138
39 -32 31 99 117 138
40 -32 31 99 117 138
41 -32 31 99 117 138
42 -32 31 99 117 138
19 -31 31 99 117 138
20 -31 31 99 117 138
21 -31 31 99 117 138
22 -31 31 99 117 138
23 -31 31 99 117 138
24 -31 31 99 117 138
25 -31 31 99 117 138
26 -31 31 99 117 138
27 -31 31 99 117 138
28 -31 31 99 117 138
29 -31 31 99 117 138
30 -31 31 99 117 138
31 -31 31 99 117 138
32 -31 31 99 117 138
33 -31 31 99 117 138
34 -31 31 99 117 138
35 -31 31 99 117 138
36 -31 31 99 117 138
37 -31 31 99 117 138
38 -31 31 99 117 138
39 -31 31 99 117 138
40 -31 31 99 117 138
41 -31 31 99 117 138
42 -31 31 99 117 138
19 -30 31 99 117 138
20 -30 31 99 117 138
21 -30 31 99 117 138
22 -30 31 99 117 138
23 -30 31 99 117 138
24 -30 31 99 117 138
25 -30 31 99 117 138
26 -30 31 99 117 138
27 -30 31 99 117 138
28 -30 31 99 117 138
29 -30 31 99 117 138
30 -30 31 99 117 138
31 -30 31 99 117 138
32 -30 31 99 117 138
33 -30 31 99 117 138
34 -30 31 99 117 138
35 -30 31 99 117 138
36 -30 31 99 117 138
37 -30 31 99 117 138
38 -30 31 99 117 138
39 -30 31 99 117 138
40 -30 31 99 117 138
41 -30 31 99 117 138
42 -30 31 99 117 138
19 -29 31 99 117 138
20 -29 31 99 117 138
21 -29 31 99 117 138
22 -29 31 99 117 138
23 -29 31 99 117 138
24 -29 31 99 117 138
25 -29 31 99 117 138
26 -29 31 99 117 138
27 -29 31 99 117 138
28 -29 31 99 117 138
29 -29 31 99 117 138
30 -29 31 99 117 138
31 -29 31 99 117 138
32 -29 31 99 117 138
33 -29 31 99 117 138
34 -29 31 99 117 138
35 -29 31 99 117 138
36 -29 31 99 117 138
37 -29 31 99 117 138
38 -29 31 99 117 138
39 -29 31 99 117 138
40 -29 31 99 117 138
41 -29 31 99 117 138
42 -29 31 99 117 138
19 -28 31 99 117 138
20 -28 31 99 117 138
21 -28 31 99 117 138
22 -28 31 99 117 138
23 -28 31 99 117 138
24 -28 31 99 117 138
25 -28 31 99 117 138
26 -28 31 99 117 138
27 -28 31 99 117 138
28 -28 31 99 117 138
29 -28 31 99 117 138
30 -28 31 99 117 138
31 -28 31 99 117 138
32 -28 31 99 117 138
33 -28 31 99 117 138
34 -28 31 99 117 138
35 -28 31 99 117 138
36 -28 31 99 117 138
37 -28 31 99 117 138
38 -28 31 99 117 138
39 -28 31 99 117 138
40 -28 31 99 117 138
41 -28 31 99 117 138
42 -28 31 99 117 138
19 -27 31 99 117 138
20 -27 31 99 117 138
21 -27 31 99 117 138
22 -27 31 99 117 138
23 -27 31 99 117 138
24 -27 31 99 117 138
25 -27 31 99 117 138
26 -27 31 99 117 138
27 -27 31 99 117 138
28 -27 31 99 117 138
29 -27 31 99 117 138
30 -27 31 99 117 138
31 -27 31 99 117 138
32 -27 31 99 117 138
33 -27 31 99 117 138
34 -27 31 99 117 138
35 -27 31 99 117 138
36 -27 31 99 117 138
37 -27 31 99 117 138
38 -27 31 99 117 138
39 -27 31 99 117 138
40 -27 31 99 117 138
41 -27 31 99 117 138
42 -27 31 99 117 138
19 -26 31 99 117 138
20 -26 31 99 117 138
21 -26 31 99 117 138
22 -26 31 99 117 138
23 -26 31 99 117 138
24 -26 31 99 117 138
25 -26 31 99 117 138
26 -26 31 99 117 138
27 -26 31 99 117 138
28 -26 31 99 117 138
29 -26 31 99 117 138
30 -26 31 99 117 138
31 -26 31 99 117 138
32 -26 31 99 117 138
33 -26 31 99 117 138
34 -26 31 99 117 138
35 -26 31 99 117 138
36 -26 31 99 117 138
37 -26 31 99 117 138
38 -26 31 99 117 138
39 -26 31 99 117 138
40 -26 31 99 117 138
41 -26 31 99 117 138
42 -26 31 99 117 138
19 -25 31 99 117 138
20 -25 31 99 117 138
21 -25 31 99 117 138
22 -25 31 99 117 138
23 -25 31 99 117 138
24 -25 31 99 117 138
25 -25 31 99 117 138
26 -25 31 99 117 138
27 -25 31 99 117 138
28 -25 31 99 117 138
29 -25 31 99 117 138
30 -25 31 99 117 138
31 -25 31 99 117 138
32 -25 31 99 117 138
33 -25 31 99 117 138
34 -25 31 99 117 138
35 -25 31 99 117 138
36 -25 31 99 117 138
37 -25 31 99 117 138
38 -25 31 99 117 138
39 -25 31 99 117 138
40 -25 31 99 117 138
41 -25 31 99 117 138
42 -25 31 99 117 138
19 -24 31 99 117 138
20 -24 31 99 117 138
21 -24 31 99 117 138
22 -24 31 99 117 138
23 -24 31 99 117 138
24 -24 31 99 117 138
25 -24 31 99 117 138
26 -24 31 99 117 138
27 -24 31 99 117 138
28 -24 31 99 117 138
29 -24 31 99 117 138
30 -24 31 99 117 138
31 -24 31 99 117 138
32 -24 31 99 117 138
33 -24 31 99 117 138
34 -24 31 99 117 138
35 -24 31 99 117 138
36 -24 31 99 117 138
37 -24 31 99 117 138
38 -24 31 99 117 138
39 -24 31 99 117 138
40 -24 31 99 117 138
41 -24 31 99 117 138
42 -24 31 99 117 138
19 -23 31 99 117 138
20 -23 31 99 117 138
21 -23 31 99 117 138
22 -23 31 99 117 138
23 -23 31 99 117 138
24 -23 31 99 117 138
25 -23 31 99 117 138
26 -23 31 99 117 138
27 -23 31 99 117 138
28 -23 31 99 117 138
29 -23 31 99 117 138
30 -23 31 99 117 138
31 -23 31 99 117 138
32 -23 31 99 117 138
33 -23 31 99 117 138
34 -23 31 99 117 138
35 -23 31 99 117 138
36 -23 31 99 117 138
37 -23 31 99 117 138
38 -23 31 99 117 138
39 -23 31 99 117 138
40 -23 31 99 117 138
41 -23 31 99 117 138
42 -23 31 99 117 138
19 -22 31 99 117 138
20 -22 31 99 117 138
21 -22 31 99 117 138
22 -22 31 99 117 138
23 -22 31 99 117 138
24 -22 31 99 117 138
25 -22 31 99 117 138
26 -22 31 99 117 138
27 -22 31 99 117 138
28 -22 31 99 117 138
29 -22 31 99 117 138
30 -22 31 99 117 138
31 -22 31 99 117 138
32 -22 31 99 117 138
33 -22 31 99 117 138
34 -22 31 99 117 138
35 -22 31 99 117 138
36 -22 31 99 117 138
37 -22 31 99 117 138
38 -22 31 99 117 138
39 -22 31 99 117 138
40 -22 31 99 117 138
41 -22 31 99 117 138
42 -22 31 99 117 138
19 -21 31 99 117 138
20 -21 31 99 117 138
21 -21 31 99 117 138
22 -21 31 99 117 138
23 -21 31 99 117 138
24 -21 31 99 117 138
25 -21 31 99 117 138
26 -21 31 99 117 138
27 -21 31 99 117 138
28 -21 31 99 117 138
29 -21 31 99 117 138
30 -21 31 99 117 138
31 -21 31 99 117 138
32 -21 31 99 117 138
33 -21 31 99 117 138
34 -21 31 99 117 138
35 -21 31 99 117 138
36 -21 31 99 117 138
37 -21 31 99 117 138
38 -21 31 99 117 138
39 -21 31 99 117 138
40 -21 31 99 117 138
41 -21 31 99 117 138
42 -21 31 99 117 138
19 -20 31 99 117 138
20 -20 31 99 117 138
21 -20 31 99 117 138
22 -20 31 99 117 138
23 -20 31 99 117 138
24 -20 31 99 117 138
25 -20 31 99 117 138
26 -20 31 99 117 138
27 -20 31 99 117 138
28 -20 31 99 117 138
29 -20 31 99 117 138
30 -20 31 99 117 138
31 -20 31 99 117 138
32 -20 31 99 117 138
33 -20 31 99 117 138
34 -20 31 99 117 138
35 -20 31 99 117 138
36 -20 31 99 117 138
37 -20 31 99 117 138
38 -20 31 99 117 138
39 -20 31 99 117 138
40 -20 31 99 117 138
41 -20 31 99 117 138
42 -20 31 99 117 138
19 -19 31 99 117 138
20 -19 31 99 117 138
21 -19 31 99 117 138
22 -19 31 99 117 138
23 -19 31 99 117 138
24 -19 31 99 117 138
25 -19 31 99 117 138
26 -19 31 99 117 138
27 -19 31 99 117 138
28 -19 31 99 117 138
29 -19 31 99 117 138
30 -19 31 99 117 138
31 -19 31 99 117 138
32 -19 31 99 117 138
33 -19 31 99 117 138
34 -19 31 99 117 138
35 -19 31 99 117 138
36 -19 31 99 117 138
37 -19 31 99 117 138
38 -19 31 99 117 138
39 -19 31 99 117 138
40 -19 31 99 117 138
41 -19 31 99 117 138
42 -19 31 99 117 138
19 -18 31 99 117 138
20 -18 31 99 117 138
21 -18 31 99 117 138
22 -18 31 99 117 138
23 -18 31 99 117 138
24 -18 31 99 117 138
25 -18 31 99 117 138
26 -18 31 99 117 138
27 -18 31 99 117 138
28 -18 31 99 117 138
29 -18 31 99 117 138
30 -18 31 99 117 138
31 -18 31 99 117 138
32 -18 31 99 117 138
33 -18 31 99 117 138
34 -18 31 99 117 138
35 -18 31 99 117 138
36 -18 31 99 117 138
37 -18 31 99 117 138
38 -18 31 99 117 138
39 -18 31 99 117 138
40 -18 31 99 117 138
41 -18 31 99 117 138
42 -18 31 99 117 138
19 -17 31 99 117 138
20 -17 31 99 117 138
21 -17 31 99 117 138
22 -17 31 99 117 138
23 -17 31 99 117 138
24 -17 31 99 117 138
25 -17 31 99 117 138
26 -17 31 99 117 138
27 -17 31 99 117 138
28 -17 31 99 117 138
29 -17 31 99 117 138
30 -17 31 99 117 138
31 -17 31 99 117 138
32 -17 31 99 117 138
33 -17 31 99 117 138
34 -17 31 99 117 138
35 -17 31 99 117 138
36 -17 31 99 117 138
37 -17 31 99 117 138
38 -17 31 99 117 138
39 -17 31 99 117 138
40 -17 31 99 117 138
41 -17 31 99 117 138
42 -17 31 99 117 138
19 -16 31 99 117 138
20 -16 31 99 117 138
21 -16 31 99 117 138
22 -16 31 99 117 138
23 -16 31 99 117 138
24 -16 31 99 117 138
25 -16 31 99 117 138
26 -16 31 99 117 138
27 -16 31 99 117 138
28 -16 31 99 117 138
29 -16 31 99 117 138
30 -16 31 99 117 138
31 -16 31 99 117 138
32 -16 31 99 117 138
33 -16 31 99 117 138
34 -16 31 99 117 138
35 -16 31 99 117 138
36 -16 31 99 117 138
37 -16 31 99 117 138
38 -16 31 99 117 138
39 -16 31 99 117 138
40 -16 31 99 117 138
41 -16 31 99 117 138
42 -16 31 99 117 138
19 -15 31 99 117 138
20 -15 31 99 117 138
21 -15 31 99 117 138
22 -15 31 99 117 138
23 -15 31 99 117 138
24 -15 31 99 117 138
25 -15 31 99 117 138
26 -15 31 99 117 138
27 -15 31 99 117 138
28 -15 31 99 117 138
29 -15 31 99 117 138
30 -15 31 99 117 138
31 -15 31 99 117 138
32 -15 31 99 117 138
33 -15 31 99 117 138
34 -15 31 99 117 138
35 -15 31 99 117 138
36 -15 31 99 117 138
37 -15 31 99 117 138
38 -15 31 99 117 138
39 -15 31 99 117 138
40 -15 31 99 117 138
41 -15 31 99 117 138
42 -15 31 99 117 138
19 -14 31 99 117 138
20 -14 31 99 117 138
21 -14 31 99 117 138
22 -14 31 99 117 138
23 -14 31 99 117 138
24 -14 31 99 117 138
25 -14 31 99 117 138
26 -14 31 99 117 138
27 -14 31 99 117 138
28 -14 31 99 117 138
29 -14 31 99 117 138
30 -14 31 99 117 138
31 -14 31 99 117 138
32 -14 31 99 117 138
33 -14 31 99 117 138
34 -14 31 99 117 138
35 -14 31 99 117 138
36 -14 31 99 117 138
37 -14 31 99 117 138
38 -14 31 99 117 138
39 -14 31 99 117 138
40 -14 31 99 117 138
41 -14 31 99 117 138
42 -14 31 99 117 138
19 -13 31 99 117 138
20 -13 31 99 117 138
21 -13 31 99 117 138
22 -13 31 99 117 138
23 -13 31 99 117 138
24 -13 31 99 117 138
25 -13 31 99 117 138
26 -13 31 99 117 138
27 -13 31 99 117 138
28 -13 31 99 117 138
29 -13 31 99 117 138
30 -13 31 99 117 138
31 -13 31 99 117 138
32 -13 31 99 117 138
33 -13 31 99 117 138
34 -13 31 99 117 138
35 -13 31 99 117 138
36 -13 31 99 117 138
37 -13 31 99 117 138
38 -13 31 99 117 138
39 -13 31 99 117 138
40 -13 31 99 117 138
41 -13 31 99 117 138
42 -13 31 99 117 138
19 -12 31 99 117 138
20 -12 31 99 117 138
21 -12 31 99 117 138
22 -12 31 99 117 138
23 -12 31 99 117 138
24 -12 31 99 117 138
25 -12 31 99 117 138
26 -12 31 99 117 138
27 -12 31 99 117 138
28 -12 31 99 117 138
29 -12 31 99 117 138
30 -12 31 99 117 138
31 -12 31 99 117 138
32 -12 31 99 117 138
33 -12 31 99 117 138
34 -12 31 99 117 138
35 -12 31 99 117 138
36 -12 31 99 117 138
37 -12 31 99 117 138
38 -12 31 99 117 138
39 -12 31 99 117 138
40 -12 31 99 117 138
41 -12 31 99 117 138
42 -12 31 99 117 138
19 -11 31 99 117 138
20 -11 31 99 117 138
21 -11 31 99 117 138
22 -11 31 99 117 138
23 -11 31 99 117 138
24 -11 31 99 117 138
25 -11 31 99 117 138
26 -11 31 99 117 138
27 -11 31 99 117 138
28 -11 31 99 117 138
29 -11 31 99 117 138
30 -11 31 99 117 138
31 -11 31 99 117 138
32 -11 31 99 117 138
33 -11 31 99 117 138
34 -11 31 99 117 138
35 -11 31 99 117 138
36 -11 31 99 117 138
37 -11 31 99 117 138
38 -11 31 99 117 138
39 -11 31 99 117 138
40 -11 31 99 117 138
41 -11 31 99 117 138
42 -11 31 99 117 138
19 -10 31 99 117 138
20 -10 31 91 108 127
21 -10 31 91 108 127
22 -10 31 99 117 138
23 -10 31 99 117 138
24 -10 31 91 108 127
25 -10 31 91 108 127
26 -10 31 99 117 138
27 -10 31 99 117 138
28 -10 31 91 108 127
29 -10 31 91 108 127
30 -10 31 99 117 138
31 -10 31 99 117 138
32 -10 31 91 108 127
33 -10 31 91 108 127
34 -10 31 99 117 138
35 -10 31 99 117 138
36 -10 31 91 108 127
37 -10 31 91 108 127
38 -10 31 99 117 138
39 -10 31 99 117 138
40 -10 31 91 108 127
41 -10 31 91 108 127
42 -10 31 99 117 138
19 -9 31 99 117 138
20 -9 31 91 108 127
21 -9 31 91 108 127
22 -9 31 99 117 138
23 -9 31 99 117 138
24 -9 31 91 108 127
25 -9 31 91 108 127
26 -9 31 99 117 138
27 -9 31 99 117 138
28 -9 31 91 108 127
29 -9 31 91 108 127
30 -9 31 99 117 138
31 -9 31 99 117 138
32 -9 31 91 108 127
33 -9 31 91 108 127
34 -9 31 99 117 138
35 -9 31 99 117 138
36 -9 31 91 108 127
37 -9 31 91 108 127
38 -9 31 99 117 138
39 -9 31 99 117 138
40 -9 31 91 108 127
41 -9 31 91 108 127
42 -9 31 99 117 138
19 -8 31 99 117 138
20 -8 31 91 108 127
21 -8 31 91 108 127
22 -8 31 99 117 138
23 -8 31 99 117 138
24 -8 31 91 108 127
25 -8 31 91 108 127
26 -8 31 99 117 138
27 -8 31 99 117 138
28 -8 31 91 108 127
29 -8 31 91 108 127
30 -8 31 99 117 138
31 -8 31 99 117 138
32 -8 31 91 108 127
33 -8 31 91 108 127
34 -8 31 99 117 138
35 -8 31 99 117 138
36 -8 31 91 108 127
37 -8 31 91 108 127
38 -8 31 99 117 138
39 -8 31 99 117 138
40 -8 31 91 108 127
41 -8 31 91 108 127
42 -8 31 99 117 138
19 -7 31 115 136 160
20 -7 31 115 136 160
21 -7 31 115 136 160
22 -7 31 115 136 160
23 -7 31 115 136 160
24 -7 31 115 136 160
25 -7 31 115 136 160
26 -7 31 115 136 160
27 -7 31 115 136 160
28 -7 31 115 136 160
29 -7 31 115 136 160
30 -7 31 115 136 160
31 -7 31 115 136 160
32 -7 31 115 136 160
33 -7 31 115 136 160
34 -7 31 115 136 160
35 -7 31 115 136 160
36 -7 31 115 136 160
37 -7 31 115 136 160
38 -7 31 115 136 160
39 -7 31 115 136 160
40 -7 31 115 136 160
41 -7 31 115 136 160
42 -7 31 115 136 160
19 -6 31 115 136 160
20 -6 31 115 136 160
21 -6 31 115 136 160
24 -6 31 115 136 160
25 -6 31 115 136 160
26 -6 31 115 136 160
27 -6 31 115 136 160
28 -6 31 115 136 160
29 -6 31 115 136 160
32 -6 31 115 136 160
33 -6 31 115 136 160
34 -6 31 115 136 160
35 -6 31 115 136 160
36 -6 31 115 136 160
37 -6 31 115 136 160
40 -6 31 115 136 160
41 -6 31 115 136 160
42 -6 31 115 136 160
19 -5 31 115 136 160
20 -5 31 115 136 160
21 -5 31 115 136 160
24 -5 31 115 136 160
25 -5 31 115 136 160
26 -5 31 115 136 160
27 -5 31 115 136 160
28 -5 31 115 136 160
29 -5 31 115 136 160
32 -5 31 115 136 160
33 -5 31 115 136 160
34 -5 31 115 136 160
35 -5 31 115 136 160
36 -5 31 115 136 160
37 -5 31 115 136 160
40 -5 31 115 136 160
41 -5 31 115 136 160
42 -5 31 115 136 160
19 -59 32 131 154 169
20 -59 32 131 154 169
21 -59 32 131 154 169
22 -59 32 131 154 169
23 -59 32 131 154 169
24 -59 32 131 154 169
25 -59 32 131 154 169
26 -59 32 131 154 169
27 -59 32 131 154 169
28 -59 32 131 154 169
29 -59 32 131 154 169
30 -59 32 131 154 169
31 -59 32 131 154 169
32 -59 32 131 154 169
33 -59 32 131 154 169
34 -59 32 131 154 169
35 -59 32 131 154 169
36 -59 32 131 154 169
37 -59 32 131 154 169
38 -59 32 131 154 169
39 -59 32 131 154 169
40 -59 32 131 154 169
41 -59 32 131 154 169
42 -59 32 131 154 169
43 -59 32 131 154 169
44 -59 32 131 154 169
45 -59 32 131 154 169
46 -59 32 131 154 169
47 -59 32 131 154 169
48 -59 32 131 154 169
49 -59 32 131 154 169
50 -59 32 131 154 169
19 -58 32 131 154 169
20 -58 32 131 154 169
21 -58 32 131 154 169
22 -58 32 131 154 169
23 -58 32 131 154 169
24 -58 32 131 154 169
25 -58 32 131 154 169
26 -58 32 131 154 169
27 -58 32 131 154 169
28 -58 32 131 154 169
29 -58 32 131 154 169
30 -58 32 131 154 169
31 -58 32 131 154 169
32 -58 32 131 154 169
33 -58 32 131 154 169
34 -58 32 131 154 169
35 -58 32 131 154 169
36 -58 32 131 154 169
37 -58 32 131 154 169
38 -58 32 131 154 169
39 -58 32 131 154 169
40 -58 32 131 154 169
41 -58 32 131 154 169
42 -58 32 131 154 169
43 -58 32 131 154 169
44 -58 32 131 154 169
45 -58 32 131 154 169
46 -58 32 131 154 169
47 -58 32 131 154 169
48 -58 32 131 154 169
49 -58 32 131 154 169
50 -58 32 131 154 169
19 -57 32 131 154 169
20 -57 32 131 154 169
21 -57 32 131 154 169
22 -57 32 131 154 169
23 -57 32 131 154 169
24 -57 32 131 154 169
25 -57 32 131 154 169
26 -57 32 131 154 169
27 -57 32 131 154 169
28 -57 32 131 154 169
29 -57 32 131 154 169
30 -57 32 131 154 169
31 -57 32 131 154 169
32 -57 32 131 154 169
33 -57 32 131 154 169
34 -57 32 131 154 169
35 -57 32 131 154 169
36 -57 32 131 154 169
37 -57 32 131 154 169
38 -57 32 131 154 169
39 -57 32 131 154 169
40 -57 32 131 154 169
41 -57 32 131 154 169
42 -57 32 131 154 169
43 -57 32 131 154 169
44 -57 32 131 154 169
45 -57 32 131 154 169
46 -57 32 131 154 169
47 -57 32 131 154 169
48 -57 32 131 154 169
49 -57 32 131 154 169
50 -57 32 131 154 169
19 -56 32 120 141 153
20 -56 32 131 154 169
21 -56 32 131 154 169
22 -56 32 131 154 169
23 -56 32 131 154 169
24 -56 32 131 154 169
25 -56 32 131 154 169
26 -56 32 131 154 169
27 -56 32 131 154 169
28 -56 32 131 154 169
29 -56 32 131 154 169
30 -56 32 131 154 169
31 -56 32 131 154 169
32 -56 32 131 154 169
33 -56 32 131 154 169
34 -56 32 131 154 169
35 -56 32 131 154 169
36 -56 32 131 154 169
37 -56 32 131 154 169
38 -56 32 131 154 169
39 -56 32 131 154 169
40 -56 32 131 154 169
41 -56 32 131 154 169
42 -56 32 131 154 169
43 -56 32 131 154 169
44 -56 32 131 154 169
45 -56 32 131 154 169
46 -56 32 131 154 169
47 -56 32 131 154 169
48 -56 32 131 154 169
49 -56 32 131 154 169
50 -56 32 120 141 153
19 -55 32 120 141 153
20 -55 32 131 154 169
21 -55 32 131 154 169
22 -55 32 131 154 169
23 -55 32 131 154 169
24 -55 32 131 154 169
25 -55 32 131 154 169
26 -55 32 131 154 169
27 -55 32 131 154 169
28 -55 32 131 154 169
29 -55 32 131 154 169
30 -55 32 131 154 169
31 -55 32 131 154 169
32 -55 32 131 154 169
33 -55 32 131 154 169
34 -55 32 131 154 169
35 -55 32 131 154 169
36 -55 32 131 154 169
37 -55 32 131 154 169
38 -55 32 131 154 169
39 -55 32 131 154 169
40 -55 32 131 154 169
41 -55 32 131 154 169
42 -55 32 131 154 169
43 -55 32 131 154 169
44 -55 32 131 154 169
45 -55 32 131 154 169
46 -55 32 131 154 169
47 -55 32 131 154 169
48 -55 32 131 154 169
49 -55 32 131 154 169
50 -55 32 120 141 153
19 -54 32 120 141 153
20 -54 32 131 154 169
21 -54 32 131 154 169
22 -54 32 131 154 169
23 -54 32 131 154 169
24 -54 32 131 154 169
25 -54 32 131 154 169
26 -54 32 131 154 169
27 -54 32 131 154 169
28 -54 32 131 154 169
29 -54 32 131 154 169
30 -54 32 131 154 169
31 -54 32 131 154 169
32 -54 32 131 154 169
33 -54 32 131 154 169
34 -54 32 131 154 169
35 -54 32 131 154 169
36 -54 32 131 154 169
37 -54 32 131 154 169
38 -54 32 131 154 169
39 -54 32 131 154 169
40 -54 32 131 154 169
41 -54 32 131 154 169
42 -54 32 131 154 169
43 -54 32 131 154 169
44 -54 32 131 154 169
45 -54 32 131 154 169
46 -54 32 131 154 169
47 -54 32 131 154 169
48 -54 32 131 154 169
49 -54 32 131 154 169
50 -54 32 120 141 153
19 -53 32 150 176 191
20 -53 32 150 176 191
21 -53 32 150 176 191
22 -53 32 150 176 191
23 -53 32 150 176 191
24 -53 32 150 176 191
25 -53 32 150 176 191
26 -53 32 150 176 191
27 -53 32 150 176 191
28 -53 32 150 176 191
29 -53 32 150 176 191
30 -53 32 150 176 191
31 -53 32 150 176 191
32 -53 32 150 176 191
33 -53 32 150 176 191
34 -53 32 150 176 191
35 -53 32 150 176 191
36 -53 32 150 176 191
37 -53 32 150 176 191
38 -53 32 150 176 191
39 -53 32 150 176 191
40 -53 32 150 176 191
41 -53 32 150 176 191
42 -53 32 150 176 191
43 -53 32 150 176 191
44 -53 32 150 176 191
45 -53 32 150 176 191
46 -53 32 150 176 191
47 -53 32 150 176 191
48 -53 32 150 176 191
49 -53 32 150 176 191
50 -53 32 150 176 191
19 -52 32 150 176 191
20 -52 32 150 176 191
21 -52 32 150 176 191
22 -52 32 150 176 191
23 -52 32 150 176 191
24 -52 32 150 176 191
25 -52 32 150 176 191
26 -52 32 150 176 191
27 -52 32 150 176 191
28 -52 32 150 176 191
29 -52 32 150 176 191
30 -52 32 150 176 191
31 -52 32 150 176 191
32 -52 32 150 176 191
33 -52 32 150 176 191
34 -52 32 150 176 191
35 -52 32 150 176 191
36 -52 32 150 176 191
37 -52 32 150 176 191
38 -52 32 150 176 191
39 -52 32 150 176 191
40 -52 32 150 176 191
41 -52 32 150 176 191
42 -52 32 150 176 191
43 -52 32 150 176 191
44 -52 32 150 176 191
45 -52 32 150 176 191
46 -52 32 150 176 191
47 -52 32 150 176 191
48 -52 32 150 176 191
49 -52 32 150 176 191
50 -52 32 150 176 191
43 -51 32 150 176 191
44 -51 32 150 176 191
45 -51 32 150 176 191
46 -51 32 150 176 191
47 -51 32 150 176 191
48 -51 32 150 176 191
49 -51 32 150 176 191
50 -51 32 150 176 191
43 -50 32 150 176 191
44 -50 32 150 176 191
45 -50 32 150 176 191
46 -50 32 150 176 191
47 -50 32 150 176 191
48 -50 32 150 176 191
49 -50 32 150 176 191
50 -50 32 150 176 191
43 -49 32 150 176 191
44 -49 32 150 176 191
45 -49 32 150 176 191
46 -49 32 150 176 191
47 -49 32 150 176 191
48 -49 32 150 176 191
49 -49 32 150 176 191
50 -49 32 150 176 191
43 -48 32 150 176 191
44 -48 32 150 176 191
45 -48 32 150 176 191
46 -48 32 150 176 191
47 -48 32 150 176 191
48 -48 32 150 176 191
49 -48 32 150 176 191
50 -48 32 150 176 191
43 -47 32 150 176 191
44 -47 32 150 176 191
45 -47 32 150 176 191
46 -47 32 150 176 191
47 -47 32 150 176 191
48 -47 32 150 176 191
49 -47 32 150 176 191
50 -47 32 150 176 191
43 -46 32 150 176 191
44 -46 32 150 176 191
45 -46 32 150 176 191
46 -46 32 150 176 191
47 -46 32 150 176 191
48 -46 32 150 176 191
49 -46 32 150 176 191
50 -46 32 150 176 191
43 -45 32 150 176 191
44 -45 32 150 176 191
45 -45 32 150 176 191
46 -45 32 150 176 191
47 -45 32 150 176 191
48 -45 32 150 176 191
49 -45 32 150 176 191
50 -45 32 150 176 191
43 -44 32 150 176 191
44 -44 32 103 121 132
45 -44 32 103 121 132
46 -44 32 103 121 132
47 -44 32 103 121 132
48 -44 32 103 121 132
49 -44 32 103 121 132
50 -44 32 150 176 191
19 -34 32 99 117 138
20 -34 32 99 117 138
21 -34 32 99 117 138
22 -34 32 99 117 138
23 -34 32 99 117 138
24 -34 32 99 117 138
25 -34 32 99 117 138
26 -34 32 99 117 138
27 -34 32 99 117 138
28 -34 32 99 117 138
29 -34 32 99 117 138
30 -34 32 99 117 138
31 -34 32 99 117 138
32 -34 32 99 117 138
33 -34 32 99 117 138
34 -34 32 99 117 138
35 -34 32 99 117 138
36 -34 32 99 117 138
37 -34 32 99 117 138
38 -34 32 99 117 138
39 -34 32 99 117 138
40 -34 32 99 117 138
41 -34 32 99 117 138
42 -34 32 99 117 138
19 -33 32 99 117 138
20 -33 32 99 117 138
21 -33 32 99 117 138
22 -33 32 99 117 138
23 -33 32 99 117 138
24 -33 32 99 117 138
25 -33 32 99 117 138
26 -33 32 99 117 138
27 -33 32 99 117 138
28 -33 32 99 117 138
29 -33 32 99 117 138
30 -33 32 99 117 138
31 -33 32 99 117 138
32 -33 32 99 117 138
33 -33 32 99 117 138
34 -33 32 99 117 138
35 -33 32 99 117 138
36 -33 32 99 117 138
37 -33 32 99 117 138
38 -33 32 99 117 138
39 -33 32 99 117 138
40 -33 32 99 117 138
41 -33 32 99 117 138
42 -33 32 99 117 138
19 -32 32 99 117 138
20 -32 32 99 117 138
21 -32 32 99 117 138
22 -32 32 99 117 138
23 -32 32 99 117 138
24 -32 32 99 117 138
25 -32 32 99 117 138
26 -32 32 99 117 138
27 -32 32 99 117 138
28 -32 32 99 117 138
29 -32 32 99 117 138
30 -32 32 99 117 138
31 -32 32 99 117 138
32 -32 32 99 117 138
33 -32 32 99 117 138
34 -32 32 99 117 138
35 -32 32 99 117 138
36 -32 32 99 117 138
37 -32 32 99 117 138
38 -32 32 99 117 138
39 -32 32 99 117 138
40 -32 32 99 117 138
41 -32 32 99 117 138
42 -32 32 99 117 138
19 -31 32 99 117 138
20 -31 32 99 117 138
21 -31 32 99 117 138
22 -31 32 99 117 138
23 -31 32 99 117 138
24 -31 32 99 117 138
25 -31 32 99 117 138
26 -31 32 99 117 138
27 -31 32 99 117 138
28 -31 32 99 117 138
29 -31 32 99 117 138
30 -31 32 99 117 138
31 -31 32 99 117 138
32 -31 32 99 117 138
33 -31 32 99 117 138
34 -31 32 99 117 138
35 -31 32 99 117 138
36 -31 32 99 117 138
37 -31 32 99 117 138
38 -31 32 99 117 138
39 -31 32 99 117 138
40 -31 32 99 117 138
41 -31 32 99 117 138
42 -31 32 99 117 138
19 -30 32 99 117 138
20 -30 32 99 117 138
21 -30 32 99 117 138
22 -30 32 99 117 138
23 -30 32 99 117 138
24 -30 32 99 117 138
25 -30 32 99 117 138
26 -30 32 99 117 138
27 -30 32 99 117 138
28 -30 32 99 117 138
29 -30 32 99 117 138
30 -30 32 99 117 138
31 -30 32 99 117 138
32 -30 32 99 117 138
33 -30 32 99 117 138
34 -30 32 99 117 138
35 -30 32 99 117 138
36 -30 32 99 117 138
37 -30 32 99 117 138
38 -30 32 99 117 138
39 -30 32 99 117 138
40 -30 32 99 117 138
41 -30 32 99 117 138
42 -30 32 99 117 138
19 -29 32 99 117 138
20 -29 32 99 117 138
21 -29 32 99 117 138
22 -29 32 99 117 138
23 -29 32 99 117 138
24 -29 32 99 117 138
25 -29 32 99 117 138
26 -29 32 99 117 138
27 -29 32 99 117 138
28 -29 32 99 117 138
29 -29 32 99 117 138
30 -29 32 99 117 138
31 -29 32 99 117 138
32 -29 32 99 117 138
33 -29 32 99 117 138
34 -29 32 99 117 138
35 -29 32 99 117 138
36 -29 32 99 117 138
37 -29 32 99 117 138
38 -29 32 99 117 138
39 -29 32 99 117 138
40 -29 32 99 117 138
41 -29 32 99 117 138
42 -29 32 99 117 138
19 -28 32 99 117 138
20 -28 32 99 117 138
21 -28 32 99 117 138
22 -28 32 99 117 138
23 -28 32 99 117 138
24 -28 32 99 117 138
25 -28 32 99 117 138
26 -28 32 99 117 138
27 -28 32 99 117 138
28 -28 32 99 117 138
29 -28 32 99 117 138
30 -28 32 99 117 138
31 -28 32 99 117 138
32 -28 32 99 117 138
33 -28 32 99 117 138
34 -28 32 99 117 138
35 -28 32 99 117 138
36 -28 32 99 117 138
37 -28 32 99 117 138
38 -28 32 99 117 138
39 -28 32 99 117 138
40 -28 32 99 117 138
41 -28 32 99 117 138
42 -28 32 99 117 138
19 -27 32 99 117 138
20 -27 32 99 117 138
21 -27 32 99 117 138
22 -27 32 99 117 138
23 -27 32 99 117 138
24 -27 32 99 117 138
25 -27 32 99 117 138
26 -27 32 99 117 138
27 -27 32 99 117 138
28 -27 32 99 117 138
29 -27 32 99 117 138
30 -27 32 99 117 138
31 -27 32 99 117 138
32 -27 32 99 117 138
33 -27 32 99 117 138
34 -27 32 99 117 138
35 -27 32 99 117 138
36 -27 32 99 117 138
37 -27 32 99 117 138
38 -27 32 99 117 138
39 -27 32 99 117 138
40 -27 32 99 117 138
41 -27 32 99 117 138
42 -27 32 99 117 138
19 -26 32 99 117 138
20 -26 32 99 117 138
21 -26 32 99 117 138
22 -26 32 99 117 138
23 -26 32 99 117 138
24 -26 32 99 117 138
25 -26 32 99 117 138
26 -26 32 99 117 138
27 -26 32 99 117 138
28 -26 32 99 117 138
29 -26 32 99 117 138
30 -26 32 99 117 138
31 -26 32 99 117 138
32 -26 32 99 117 138
33 -26 32 99 117 138
34 -26 32 99 117 138
35 -26 32 99 117 138
36 -26 32 99 117 138
37 -26 32 99 117 138
38 -26 32 99 117 138
39 -26 32 99 117 138
40 -26 32 99 117 138
41 -26 32 99 117 138
42 -26 32 99 117 138
19 -25 32 99 117 138
20 -25 32 99 117 138
21 -25 32 99 117 138
22 -25 32 99 117 138
23 -25 32 99 117 138
24 -25 32 99 117 138
25 -25 32 99 117 138
26 -25 32 99 117 138
27 -25 32 99 117 138
28 -25 32 99 117 138
29 -25 32 99 117 138
30 -25 32 99 117 138
31 -25 32 99 117 138
32 -25 32 99 117 138
33 -25 32 99 117 138
34 -25 32 99 117 138
35 -25 32 99 117 138
36 -25 32 99 117 138
37 -25 32 99 117 138
38 -25 32 99 117 138
39 -25 32 99 117 138
40 -25 32 99 117 138
41 -25 32 99 117 138
42 -25 32 99 117 138
19 -24 32 99 117 138
20 -24 32 99 117 138
21 -24 32 99 117 138
22 -24 32 99 117 138
23 -24 32 99 117 138
24 -24 32 99 117 138
25 -24 32 99 117 138
26 -24 32 99 117 138
27 -24 32 99 117 138
28 -24 32 99 117 138
29 -24 32 99 117 138
30 -24 32 99 117 138
31 -24 32 99 117 138
32 -24 32 99 117 138
33 -24 32 99 117 138
34 -24 32 99 117 138
35 -24 32 99 117 138
36 -24 32 99 117 138
37 -24 32 99 117 138
38 -24 32 99 117 138
39 -24 32 99 117 138
40 -24 32 99 117 138
41 -24 32 99 117 138
42 -24 32 99 117 138
19 -23 32 99 117 138
20 -23 32 99 117 138
21 -23 32 99 117 138
22 -23 32 99 117 138
23 -23 32 99 117 138
24 -23 32 99 117 138
25 -23 32 99 117 138
26 -23 32 99 117 138
27 -23 32 99 117 138
28 -23 32 99 117 138
29 -23 32 99 117 138
30 -23 32 99 117 138
31 -23 32 99 117 138
32 -23 32 99 117 138
33 -23 32 99 117 138
34 -23 32 99 117 138
35 -23 32 99 117 138
36 -23 32 99 117 138
37 -23 32 99 117 138
38 -23 32 99 117 138
39 -23 32 99 117 138
40 -23 32 99 117 138
41 -23 32 99 117 138
42 -23 32 99 117 138
19 -22 32 99 117 138
20 -22 32 99 117 138
21 -22 32 99 117 138
22 -22 32 99 117 138
23 -22 32 99 117 138
24 -22 32 99 117 138
25 -22 32 99 117 138
26 -22 32 99 117 138
27 -22 32 99 117 138
28 -22 32 99 117 138
29 -22 32 99 117 138
30 -22 32 99 117 138
31 -22 32 99 117 138
32 -22 32 99 117 138
33 -22 32 99 117 138
34 -22 32 99 117 138
35 -22 32 99 117 138
36 -22 32 99 117 138
37 -22 32 99 117 138
38 -22 32 99 117 138
39 -22 32 99 117 138
40 -22 32 99 117 138
41 -22 32 99 117 138
42 -22 32 99 117 138
19 -21 32 99 117 138
20 -21 32 99 117 138
21 -21 32 99 117 138
22 -21 32 99 117 138
23 -21 32 99 117 138
24 -21 32 99 117 138
25 -21 32 99 117 138
26 -21 32 99 117 138
27 -21 32 99 117 138
28 -21 32 99 117 138
29 -21 32 99 117 138
30 -21 32 99 117 138
31 -21 32 99 117 138
32 -21 32 99 117 138
33 -21 32 99 117 138
34 -21 32 99 117 138
35 -21 32 99 117 138
36 -21 32 99 117 138
37 -21 32 99 117 138
38 -21 32 99 117 138
39 -21 32 99 117 138
40 -21 32 99 117 138
41 -21 32 99 117 138
42 -21 32 99 117 138
19 -20 32 99 117 138
20 -20 32 99 117 138
21 -20 32 99 117 138
22 -20 32 99 117 138
23 -20 32 99 117 138
24 -20 32 99 117 138
25 -20 32 99 117 138
26 -20 32 99 117 138
27 -20 32 99 117 138
28 -20 32 99 117 138
29 -20 32 99 117 138
30 -20 32 99 117 138
31 -20 32 99 117 138
32 -20 32 99 117 138
33 -20 32 99 117 138
34 -20 32 99 117 138
35 -20 32 99 117 138
36 -20 32 99 117 138
37 -20 32 99 117 138
38 -20 32 99 117 138
39 -20 32 99 117 138
40 -20 32 99 117 138
41 -20 32 99 117 138
42 -20 32 99 117 138
19 -19 32 99 117 138
20 -19 32 99 117 138
21 -19 32 99 117 138
22 -19 32 99 117 138
23 -19 32 99 117 138
24 -19 32 99 117 138
25 -19 32 99 117 138
26 -19 32 99 117 138
27 -19 32 99 117 138
28 -19 32 99 117 138
29 -19 32 99 117 138
30 -19 32 99 117 138
31 -19 32 99 117 138
32 -19 32 99 117 138
33 -19 32 99 117 138
34 -19 32 99 117 138
35 -19 32 99 117 138
36 -19 32 99 117 138
37 -19 32 99 117 138
38 -19 32 99 117 138
39 -19 32 99 117 138
40 -19 32 99 117 138
41 -19 32 99 117 138
42 -19 32 99 117 138
19 -18 32 99 117 138
20 -18 32 99 117 138
21 -18 32 99 117 138
22 -18 32 99 117 138
23 -18 32 99 117 138
24 -18 32 99 117 138
25 -18 32 99 117 138
26 -18 32 99 117 138
27 -18 32 99 117 138
28 -18 32 99 117 138
29 -18 32 99 117 138
30 -18 32 99 117 138
31 -18 32 99 117 138
32 -18 32 99 117 138
33 -18 32 99 117 138
34 -18 32 99 117 138
35 -18 32 99 117 138
36 -18 32 99 117 138
37 -18 32 99 117 138
38 -18 32 99 117 138
39 -18 32 99 117 138
40 -18 32 99 117 138
41 -18 32 99 117 138
42 -18 32 99 117 138
19 -17 32 99 117 138
20 -17 32 99 117 138
21 -17 32 99 117 138
22 -17 32 99 117 138
23 -17 32 99 117 138
24 -17 32 99 117 138
25 -17 32 99 117 138
26 -17 32 99 117 138
27 -17 32 99 117 138
28 -17 32 99 117 138
29 -17 32 99 117 138
30 -17 32 99 117 138
31 -17 32 99 117 138
32 -17 32 99 117 138
33 -17 32 99 117 138
34 -17 32 99 117 138
35 -17 32 99 117 138
36 -17 32 99 117 138
37 -17 32 99 117 138
38 -17 32 99 117 138
39 -17 32 99 117 138
40 -17 32 99 117 138
41 -17 32 99 117 138
42 -17 32 99 117 138
19 -16 32 99 117 138
20 -16 32 99 117 138
21 -16 32 99 117 138
22 -16 32 99 117 138
23 -16 32 99 117 138
24 -16 32 99 117 138
25 -16 32 99 117 138
26 -16 32 99 117 138
27 -16 32 99 117 138
28 -16 32 99 117 138
29 -16 32 99 117 138
30 -16 32 99 117 138
31 -16 32 99 117 138
32 -16 32 99 117 138
33 -16 32 99 117 138
34 -16 32 99 117 138
35 -16 32 99 117 138
36 -16 32 99 117 138
37 -16 32 99 117 138
38 -16 32 99 117 138
39 -16 32 99 117 138
40 -16 32 99 117 138
41 -16 32 99 117 138
42 -16 32 99 117 138
19 -15 32 99 117 138
20 -15 32 99 117 138
21 -15 32 99 117 138
22 -15 32 99 117 138
23 -15 32 99 117 138
24 -15 32 99 117 138
25 -15 32 99 117 138
26 -15 32 99 117 138
27 -15 32 99 117 138
28 -15 32 99 117 138
29 -15 32 99 117 138
30 -15 32 99 117 138
31 -15 32 99 117 138
32 -15 32 99 117 138
33 -15 32 99 117 138
34 -15 32 99 117 138
35 -15 32 99 117 138
36 -15 32 99 117 138
37 -15 32 99 117 138
38 -15 32 99 117 138
39 -15 32 99 117 138
40 -15 32 99 117 138
41 -15 32 99 117 138
42 -15 32 99 117 138
19 -14 32 99 117 138
20 -14 32 99 117 138
21 -14 32 99 117 138
22 -14 32 99 117 138
23 -14 32 99 117 138
24 -14 32 99 117 138
25 -14 32 99 117 138
26 -14 32 99 117 138
27 -14 32 99 117 138
28 -14 32 99 117 138
29 -14 32 99 117 138
30 -14 32 99 117 138
31 -14 32 99 117 138
32 -14 32 99 117 138
33 -14 32 99 117 138
34 -14 32 99 117 138
35 -14 32 99 117 138
36 -14 32 99 117 138
37 -14 32 99 117 138
38 -14 32 99 117 138
39 -14 32 99 117 138
40 -14 32 99 117 138
41 -14 32 99 117 138
42 -14 32 99 117 138
19 -13 32 99 117 138
20 -13 32 99 117 138
21 -13 32 99 117 138
22 -13 32 99 117 138
23 -13 32 99 117 138
24 -13 32 99 117 138
25 -13 32 99 117 138
26 -13 32 99 117 138
27 -13 32 99 117 138
28 -13 32 99 117 138
29 -13 32 99 117 138
30 -13 32 99 117 138
31 -13 32 99 117 138
32 -13 32 99 117 138
33 -13 32 99 117 138
34 -13 32 99 117 138
35 -13 32 99 117 138
36 -13 32 99 117 138
37 -13 32 99 117 138
38 -13 32 99 117 138
39 -13 32 99 117 138
40 -13 32 99 117 138
41 -13 32 99 117 138
42 -13 32 99 117 138
19 -12 32 99 117 138
20 -12 32 99 117 138
21 -12 32 99 117 138
22 -12 32 99 117 138
23 -12 32 99 117 138
24 -12 32 99 117 138
25 -12 32 99 117 138
26 -12 32 99 117 138
27 -12 32 99 117 138
28 -12 32 99 117 138
29 -12 32 99 117 138
30 -12 32 99 117 138
31 -12 32 99 117 138
32 -12 32 99 117 138
33 -12 32 99 117 138
34 -12 32 99 117 138
35 -12 32 99 117 138
36 -12 32 99 117 138
37 -12 32 99 117 138
38 -12 32 99 117 138
39 -12 32 99 117 138
40 -12 32 99 117 138
41 -12 32 99 117 138
42 -12 32 99 117 138
19 -11 32 99 117 138
20 -11 32 99 117 138
21 -11 32 99 117 138
22 -11 32 99 117 138
23 -11 32 99 117 138
24 -11 32 99 117 138
25 -11 32 99 117 138
26 -11 32 99 117 138
27 -11 32 99 117 138
28 -11 32 99 117 138
29 -11 32 99 117 138
30 -11 32 99 117 138
31 -11 32 99 117 138
32 -11 32 99 117 138
33 -11 32 99 117 138
34 -11 32 99 117 138
35 -11 32 99 117 138
36 -11 32 99 117 138
37 -11 32 99 117 138
38 -11 32 99 117 138
39 -11 32 99 117 138
40 -11 32 99 117 138
41 -11 32 99 117 138
42 -11 32 99 117 138
19 -10 32 91 108 127
20 -10 32 99 117 138
21 -10 32 99 117 138
22 -10 32 99 117 138
23 -10 32 99 117 138
24 -10 32 99 117 138
25 -10 32 99 117 138
26 -10 32 99 117 138
27 -10 32 99 117 138
28 -10 32 99 117 138
29 -10 32 99 117 138
30 -10 32 99 117 138
31 -10 32 99 117 138
32 -10 32 99 117 138
33 -10 32 99 117 138
34 -10 32 99 117 138
35 -10 32 99 117 138
36 -10 32 99 117 138
37 -10 32 99 117 138
38 -10 32 99 117 138
39 -10 32 99 117 138
40 -10 32 99 117 138
41 -10 32 99 117 138
42 -10 32 91 108 127
19 -9 32 91 108 127
20 -9 32 99 117 138
21 -9 32 99 117 138
22 -9 32 99 117 138
23 -9 32 99 117 138
24 -9 32 99 117 138
25 -9 32 99 117 138
26 -9 32 99 117 138
27 -9 32 99 117 138
28 -9 32 99 117 138
29 -9 32 99 117 138
30 -9 32 99 117 138
31 -9 32 99 117 138
32 -9 32 99 117 138
33 -9 32 99 117 138
34 -9 32 99 117 138
35 -9 32 99 117 138
36 -9 32 99 117 138
37 -9 32 99 117 138
38 -9 32 99 117 138
39 -9 32 99 117 138
40 -9 32 99 117 138
41 -9 32 99 117 138
42 -9 32 91 108 127
19 -8 32 91 108 127
20 -8 32 99 117 138
21 -8 32 99 117 138
22 -8 32 99 117 138
23 -8 32 99 117 138
24 -8 32 99 117 138
25 -8 32 99 117 138
26 -8 32 99 117 138
27 -8 32 99 117 138
28 -8 32 99 117 138
29 -8 32 99 117 138
30 -8 32 99 117 138
31 -8 32 99 117 138
32 -8 32 99 117 138
33 -8 32 99 117 138
34 -8 32 99 117 138
35 -8 32 99 117 138
36 -8 32 99 117 138
37 -8 32 99 117 138
38 -8 32 99 117 138
39 -8 32 99 117 138
40 -8 32 99 117 138
41 -8 32 99 117 138
42 -8 32 91 108 127
19 -7 32 115 136 160
20 -7 32 115 136 160
21 -7 32 115 136 160
22 -7 32 115 136 160
23 -7 32 115 136 160
24 -7 32 115 136 160
25 -7 32 115 136 160
26 -7 32 115 136 160
27 -7 32 115 136 160
28 -7 32 115 136 160
29 -7 32 115 136 160
30 -7 32 115 136 160
31 -7 32 115 136 160
32 -7 32 115 136 160
33 -7 32 115 136 160
34 -7 32 115 136 160
35 -7 32 115 136 160
36 -7 32 115 136 160
37 -7 32 115 136 160
38 -7 32 115 136 160
39 -7 32 115 136 160
40 -7 32 115 136 160
41 -7 32 115 136 160
42 -7 32 115 136 160
19 -6 32 115 136 160
42 -6 32 115 136 160
19 -5 32 115 136 160
42 -5 32 115 136 160
19 -59 33 131 154 169
20 -59 33 131 154 169
21 -59 33 131 154 169
22 -59 33 131 154 169
23 -59 33 131 154 169
24 -59 33 131 154 169
25 -59 33 131 154 169
26 -59 33 131 154 169
27 -59 33 131 154 169
28 -59 33 131 154 169
29 -59 33 131 154 169
30 -59 33 131 154 169
31 -59 33 131 154 169
32 -59 33 131 154 169
33 -59 33 131 154 169
34 -59 33 131 154 169
35 -59 33 131 154 169
36 -59 33 131 154 169
37 -59 33 131 154 169
38 -59 33 131 154 169
39 -59 33 131 154 169
40 -59 33 131 154 169
41 -59 33 131 154 169
42 -59 33 131 154 169
43 -59 33 131 154 169
44 -59 33 131 154 169
45 -59 33 131 154 169
46 -59 33 131 154 169
47 -59 33 131 154 169
48 -59 33 131 154 169
49 -59 33 131 154 169
50 -59 33 131 154 169
19 -58 33 131 154 169
20 -58 33 131 154 169
21 -58 33 131 154 169
22 -58 33 131 154 169
23 -58 33 131 154 169
24 -58 33 131 154 169
25 -58 33 131 154 169
26 -58 33 131 154 169
27 -58 33 131 154 169
28 -58 33 131 154 169
29 -58 33 131 154 169
30 -58 33 131 154 169
31 -58 33 131 154 169
32 -58 33 131 154 169
33 -58 33 131 154 169
34 -58 33 131 154 169
35 -58 33 131 154 169
36 -58 33 131 154 169
37 -58 33 131 154 169
38 -58 33 131 154 169
39 -58 33 131 154 169
40 -58 33 131 154 169
41 -58 33 131 154 169
42 -58 33 131 154 169
43 -58 33 131 154 169
44 -58 33 131 154 169
45 -58 33 131 154 169
46 -58 33 131 154 169
47 -58 33 131 154 169
48 -58 33 131 154 169
49 -58 33 131 154 169
50 -58 33 131 154 169
19 -57 33 131 154 169
20 -57 33 131 154 169
21 -57 33 131 154 169
22 -57 33 131 154 169
23 -57 33 131 154 169
24 -57 33 131 154 169
25 -57 33 131 154 169
26 -57 33 131 154 169
27 -57 33 131 154 169
28 -57 33 131 154 169
29 -57 33 131 154 169
30 -57 33 131 154 169
31 -57 33 131 154 169
32 -57 33 131 154 169
33 -57 33 131 154 169
34 -57 33 131 154 169
35 -57 33 131 154 169
36 -57 33 131 154 169
37 -57 33 131 154 169
38 -57 33 131 154 169
39 -57 33 131 154 169
40 -57 33 131 154 169
41 -57 33 131 154 169
42 -57 33 131 154 169
43 -57 33 131 154 169
44 -57 33 131 154 169
45 -57 33 131 154 169
46 -57 33 131 154 169
47 -57 33 131 154 169
48 -57 33 131 154 169
49 -57 33 131 154 169
50 -57 33 131 154 169
19 -56 33 120 141 153
20 -56 33 131 154 169
21 -56 33 131 154 169
22 -56 33 131 154 169
23 -56 33 131 154 169
24 -56 33 131 154 169
25 -56 33 131 154 169
26 -56 33 131 154 169
27 -56 33 131 154 169
28 -56 33 131 154 169
29 -56 33 131 154 169
30 -56 33 131 154 169
31 -56 33 131 154 169
32 -56 33 131 154 169
33 -56 33 131 154 169
34 -56 33 131 154 169
35 -56 33 131 154 169
36 -56 33 131 154 169
37 -56 33 131 154 169
38 -56 33 131 154 169
39 -56 33 131 154 169
40 -56 33 131 154 169
41 -56 33 131 154 169
42 -56 33 131 154 169
43 -56 33 131 154 169
44 -56 33 131 154 169
45 -56 33 131 154 169
46 -56 33 131 154 169
47 -56 33 131 154 169
48 -56 33 131 154 169
49 -56 33 131 154 169
50 -56 33 120 141 153
19 -55 33 120 141 153
20 -55 33 131 154 169
21 -55 33 131 154 169
22 -55 33 131 154 169
23 -55 33 131 154 169
24 -55 33 131 154 169
25 -55 33 131 154 169
26 -55 33 131 154 169
27 -55 33 131 154 169
28 -55 33 131 154 169
29 -55 33 131 154 169
30 -55 33 131 154 169
31 -55 33 131 154 169
32 -55 33 131 154 169
33 -55 33 131 154 169
34 -55 33 131 154 169
35 -55 33 131 154 169
36 -55 33 131 154 169
37 -55 33 131 154 169
38 -55 33 131 154 169
39 -55 33 131 154 169
40 -55 33 131 154 169
41 -55 33 131 154 169
42 -55 33 131 154 169
43 -55 33 131 154 169
44 -55 33 131 154 169
45 -55 33 131 154 169
46 -55 33 131 154 169
47 -55 33 131 154 169
48 -55 33 131 154 169
49 -55 33 131 154 169
50 -55 33 120 141 153
19 -54 33 120 141 153
20 -54 33 131 154 169
21 -54 33 131 154 169
22 -54 33 131 154 169
23 -54 33 131 154 169
24 -54 33 131 154 169
25 -54 33 131 154 169
26 -54 33 131 154 169
27 -54 33 131 154 169
28 -54 33 131 154 169
29 -54 33 131 154 169
30 -54 33 131 154 169
31 -54 33 131 154 169
32 -54 33 131 154 169
33 -54 33 131 154 169
34 -54 33 131 154 169
35 -54 33 131 154 169
36 -54 33 131 154 169
37 -54 33 131 154 169
38 -54 33 131 154 169
39 -54 33 131 154 169
40 -54 33 131 154 169
41 -54 33 131 154 169
42 -54 33 131 154 169
43 -54 33 131 154 169
44 -54 33 131 154 169
45 -54 33 131 154 169
46 -54 33 131 154 169
47 -54 33 131 154 169
48 -54 33 131 154 169
49 -54 33 131 154 169
50 -54 33 120 141 153
19 -53 33 150 176 191
20 -53 33 150 176 191
21 -53 33 150 176 191
22 -53 33 150 176 191
23 -53 33 150 176 191
24 -53 33 150 176 191
25 -53 33 150 176 191
26 -53 33 150 176 191
27 -53 33 150 176 191
28 -53 33 150 176 191
29 -53 33 150 176 191
30 -53 33 150 176 191
31 -53 33 150 176 191
32 -53 33 150 176 191
33 -53 33 150 176 191
34 -53 33 150 176 191
35 -53 33 150 176 191
36 -53 33 150 176 191
37 -53 33 150 176 191
38 -53 33 150 176 191
39 -53 33 150 176 191
40 -53 33 150 176 191
41 -53 33 150 176 191
42 -53 33 150 176 191
43 -53 33 150 176 191
44 -53 33 150 176 191
45 -53 33 150 176 191
46 -53 33 150 176 191
47 -53 33 150 176 191
48 -53 33 150 176 191
49 -53 33 150 176 191
50 -53 33 150 176 191
19 -52 33 150 176 191
20 -52 33 150 176 191
21 -52 33 150 176 191
22 -52 33 150 176 191
23 -52 33 150 176 191
24 -52 33 150 176 191
25 -52 33 150 176 191
26 -52 33 150 176 191
27 -52 33 150 176 191
28 -52 33 150 176 191
29 -52 33 150 176 191
30 -52 33 150 176 191
31 -52 33 150 176 191
32 -52 33 150 176 191
33 -52 33 150 176 191
34 -52 33 150 176 191
35 -52 33 150 176 191
36 -52 33 150 176 191
37 -52 33 150 176 191
38 -52 33 150 176 191
39 -52 33 150 176 191
40 -52 33 150 176 191
41 -52 33 150 176 191
42 -52 33 150 176 191
43 -52 33 150 176 191
44 -52 33 150 176 191
45 -52 33 150 176 191
46 -52 33 150 176 191
47 -52 33 150 176 191
48 -52 33 150 176 191
49 -52 33 150 176 191
50 -52 33 150 176 191
43 -51 33 150 176 191
44 -51 33 150 176 191
45 -51 33 150 176 191
46 -51 33 150 176 191
47 -51 33 150 176 191
48 -51 33 150 176 191
49 -51 33 150 176 191
50 -51 33 150 176 191
43 -50 33 150 176 191
44 -50 33 150 176 191
45 -50 33 150 176 191
46 -50 33 150 176 191
47 -50 33 150 176 191
48 -50 33 150 176 191
49 -50 33 150 176 191
50 -50 33 150 176 191
43 -49 33 150 176 191
44 -49 33 150 176 191
45 -49 33 150 176 191
46 -49 33 150 176 191
47 -49 33 150 176 191
48 -49 33 150 176 191
49 -49 33 150 176 191
50 -49 33 150 176 191
43 -48 33 150 176 191
44 -48 33 150 176 191
45 -48 33 150 176 191
46 -48 33 150 176 191
47 -48 33 150 176 191
48 -48 33 150 176 191
49 -48 33 150 176 191
50 -48 33 150 176 191
43 -47 33 150 176 191
44 -47 33 150 176 191
45 -47 33 150 176 191
46 -47 33 150 176 191
47 -47 33 150 176 191
48 -47 33 150 176 191
49 -47 33 150 176 191
50 -47 33 150 176 191
43 -46 33 150 176 191
44 -46 33 150 176 191
45 -46 33 150 176 191
46 -46 33 150 176 191
47 -46 33 150 176 191
48 -46 33 150 176 191
49 -46 33 150 176 191
50 -46 33 150 176 191
43 -45 33 150 176 191
44 -45 33 150 176 191
45 -45 33 150 176 191
46 -45 33 150 176 191
47 -45 33 150 176 191
48 -45 33 150 176 191
49 -45 33 150 176 191
50 -45 33 150 176 191
43 -44 33 150 176 191
44 -44 33 103 121 132
45 -44 33 150 176 191
46 -44 33 150 176 191
47 -44 33 150 176 191
48 -44 33 150 176 191
49 -44 33 103 121 132
50 -44 33 150 176 191
19 -34 33 99 117 138
20 -34 33 99 117 138
21 -34 33 99 117 138
22 -34 33 99 117 138
23 -34 33 99 117 138
24 -34 33 99 117 138
25 -34 33 99 117 138
26 -34 33 99 117 138
27 -34 33 99 117 138
28 -34 33 99 117 138
29 -34 33 99 117 138
30 -34 33 99 117 138
31 -34 33 99 117 138
32 -34 33 99 117 138
33 -34 33 99 117 138
34 -34 33 99 117 138
35 -34 33 99 117 138
36 -34 33 99 117 138
37 -34 33 99 117 138
38 -34 33 99 117 138
39 -34 33 99 117 138
40 -34 33 99 117 138
41 -34 33 99 117 138
42 -34 33 99 117 138
19 -33 33 99 117 138
20 -33 33 99 117 138
21 -33 33 99 117 138
22 -33 33 99 117 138
23 -33 33 99 117 138
24 -33 33 99 117 138
25 -33 33 99 117 138
26 -33 33 99 117 138
27 -33 33 99 117 138
28 -33 33 99 117 138
29 -33 33 99 117 138
30 -33 33 99 117 138
31 -33 33 99 117 138
32 -33 33 99 117 138
33 -33 33 99 117 138
34 -33 33 99 117 138
35 -33 33 99 117 138
36 -33 33 99 117 138
37 -33 33 99 117 138
38 -33 33 99 117 138
39 -33 33 99 117 138
40 -33 33 99 117 138
41 -33 33 99 117 138
42 -33 33 99 117 138
19 -32 33 99 117 138
20 -32 33 99 117 138
21 -32 33 99 117 138
22 -32 33 99 117 138
23 -32 33 99 117 138
24 -32 33 99 117 138
25 -32 33 99 117 138
26 -32 33 99 117 138
27 -32 33 99 117 138
28 -32 33 99 117 138
29 -32 33 99 117 138
30 -32 33 99 117 138
31 -32 33 99 117 138
32 -32 33 99 117 138
33 -32 33 99 117 138
34 -32 33 99 117 138
35 -32 33 99 117 138
36 -32 33 99 117 138
37 -32 33 99 117 138
38 -32 33 99 117 138
39 -32 33 99 117 138
40 -32 33 99 117 138
41 -32 33 99 117 138
42 -32 33 99 117 138
19 -31 33 99 117 138
20 -31 33 99 117 138
21 -31 33 99 117 138
22 -31 33 99 117 138
23 -31 33 99 117 138
24 -31 33 99 117 138
25 -31 33 99 117 138
26 -31 33 99 117 138
27 -31 33 99 117 138
28 -31 33 99 117 138
29 -31 33 99 117 138
30 -31 33 99 117 138
31 -31 33 99 117 138
32 -31 33 99 117 138
33 -31 33 99 117 138
34 -31 33 99 117 138
35 -31 33 99 117 138
36 -31 33 99 117 138
37 -31 33 99 117 138
38 -31 33 99 117 138
39 -31 33 99 117 138
40 -31 33 99 117 138
41 -31 33 99 117 138
42 -31 33 99 117 138
19 -30 33 99 117 138
20 -30 33 99 117 138
21 -30 33 99 117 138
22 -30 33 99 117 138
23 -30 33 99 117 138
24 -30 33 99 117 138
25 -30 33 99 117 138
26 -30 33 99 117 138
27 -30 33 99 117 138
28 -30 33 99 117 138
29 -30 33 99 117 138
30 -30 33 99 117 138
31 -30 33 99 117 138
32 -30 33 99 117 138
33 -30 33 99 117 138
34 -30 33 99 117 138
35 -30 33 99 117 138
36 -30 33 99 117 138
37 -30 33 99 117 138
38 -30 33 99 117 138
39 -30 33 99 117 138
40 -30 33 99 117 138
41 -30 33 99 117 138
42 -30 33 99 117 138
19 -29 33 99 117 138
20 -29 33 99 117 138
21 -29 33 99 117 138
22 -29 33 99 117 138
23 -29 33 99 117 138
24 -29 33 99 117 138
25 -29 33 99 117 138
26 -29 33 99 117 138
27 -29 33 99 117 138
28 -29 33 99 117 138
29 -29 33 99 117 138
30 -29 33 99 117 138
31 -29 33 99 117 138
32 -29 33 99 117 138
33 -29 33 99 117 138
34 -29 33 99 117 138
35 -29 33 99 117 138
36 -29 33 99 117 138
37 -29 33 99 117 138
38 -29 33 99 117 138
39 -29 33 99 117 138
40 -29 33 99 117 138
41 -29 33 99 117 138
42 -29 33 99 117 138
19 -28 33 99 117 138
20 -28 33 99 117 138
21 -28 33 99 117 138
22 -28 33 99 117 138
23 -28 33 99 117 138
24 -28 33 99 117 138
25 -28 33 99 117 138
26 -28 33 99 117 138
27 -28 33 99 117 138
28 -28 33 99 117 138
29 -28 33 99 117 138
30 -28 33 99 117 138
31 -28 33 99 117 138
32 -28 33 99 117 138
33 -28 33 99 117 138
34 -28 33 99 117 138
35 -28 33 99 117 138
36 -28 33 99 117 138
37 -28 33 99 117 138
38 -28 33 99 117 138
39 -28 33 99 117 138
40 -28 33 99 117 138
41 -28 33 99 117 138
42 -28 33 99 117 138
19 -27 33 99 117 138
20 -27 33 99 117 138
21 -27 33 99 117 138
22 -27 33 99 117 138
23 -27 33 99 117 138
24 -27 33 99 117 138
25 -27 33 99 117 138
26 -27 33 99 117 138
27 -27 33 99 117 138
28 -27 33 99 117 138
29 -27 33 99 117 138
30 -27 33 99 117 138
31 -27 33 99 117 138
32 -27 33 99 117 138
33 -27 33 99 117 138
34 -27 33 99 117 138
35 -27 33 99 117 138
36 -27 33 99 117 138
37 -27 33 99 117 138
38 -27 33 99 117 138
39 -27 33 99 117 138
40 -27 33 99 117 138
41 -27 33 99 117 138
42 -27 33 99 117 138
19 -26 33 99 117 138
20 -26 33 99 117 138
21 -26 33 99 117 138
22 -26 33 99 117 138
23 -26 33 99 117 138
24 -26 33 99 117 138
25 -26 33 99 117 138
26 -26 33 99 117 138
27 -26 33 99 117 138
28 -26 33 99 117 138
29 -26 33 99 117 138
30 -26 33 99 117 138
31 -26 33 99 117 138
32 -26 33 99 117 138
33 -26 33 99 117 138
34 -26 33 99 117 138
35 -26 33 99 117 138
36 -26 33 99 117 138
37 -26 33 99 117 138
38 -26 33 99 117 138
39 -26 33 99 117 138
40 -26 33 99 117 138
41 -26 33 99 117 138
42 -26 33 99 117 138
19 -25 33 99 117 138
20 -25 33 99 117 138
21 -25 33 99 117 138
22 -25 33 99 117 138
23 -25 33 99 117 138
24 -25 33 99 117 138
25 -25 33 99 117 138
26 -25 33 99 117 138
27 -25 33 99 117 138
28 -25 33 99 117 138
29 -25 33 99 117 138
30 -25 33 99 117 138
31 -25 33 99 117 138
32 -25 33 99 117 138
33 -25 33 99 117 138
34 -25 33 99 117 138
35 -25 33 99 117 138
36 -25 33 99 117 138
37 -25 33 99 117 138
38 -25 33 99 117 138
39 -25 33 99 117 138
40 -25 33 99 117 138
41 -25 33 99 117 138
42 -25 33 99 117 138
19 -24 33 99 117 138
20 -24 33 99 117 138
21 -24 33 99 117 138
22 -24 33 99 117 138
23 -24 33 99 117 138
24 -24 33 99 117 138
25 -24 33 99 117 138
26 -24 33 99 117 138
27 -24 33 99 117 138
28 -24 33 99 117 138
29 -24 33 99 117 138
30 -24 33 99 117 138
31 -24 33 99 117 138
32 -24 33 99 117 138
33 -24 33 99 117 138
34 -24 33 99 117 138
35 -24 33 99 117 138
36 -24 33 99 117 138
37 -24 33 99 117 138
38 -24 33 99 117 138
39 -24 33 99 117 138
40 -24 33 99 117 138
41 -24 33 99 117 138
42 -24 33 99 117 138
19 -23 33 99 117 138
20 -23 33 99 117 138
21 -23 33 99 117 138
22 -23 33 99 117 138
23 -23 33 99 117 138
24 -23 33 99 117 138
25 -23 33 99 117 138
26 -23 33 99 117 138
27 -23 33 99 117 138
28 -23 33 99 117 138
29 -23 33 99 117 138
30 -23 33 99 117 138
31 -23 33 99 117 138
32 -23 33 99 117 138
33 -23 33 99 117 138
34 -23 33 99 117 138
35 -23 33 99 117 138
36 -23 33 99 117 138
37 -23 33 99 117 138
38 -23 33 99 117 138
39 -23 33 99 117 138
40 -23 33 99 117 138
41 -23 33 99 117 138
42 -23 33 99 117 138
19 -22 33 99 117 138
20 -22 33 99 117 138
21 -22 33 99 117 138
22 -22 33 99 117 138
23 -22 33 99 117 138
24 -22 33 99 117 138
25 -22 33 99 117 138
26 -22 33 99 117 138
27 -22 33 99 117 138
28 -22 33 99 117 138
29 -22 33 99 117 138
30 -22 33 99 117 138
31 -22 33 99 117 138
32 -22 33 99 117 138
33 -22 33 99 117 138
34 -22 33 99 117 138
35 -22 33 99 117 138
36 -22 33 99 117 138
37 -22 33 99 117 138
38 -22 33 99 117 138
39 -22 33 99 117 138
40 -22 33 99 117 138
41 -22 33 99 117 138
42 -22 33 99 117 138
19 -21 33 99 117 138
20 -21 33 99 117 138
21 -21 33 99 117 138
22 -21 33 99 117 138
23 -21 33 99 117 138
24 -21 33 99 117 138
25 -21 33 99 117 138
26 -21 33 99 117 138
27 -21 33 99 117 138
28 -21 33 99 117 138
29 -21 33 99 117 138
30 -21 33 99 117 138
31 -21 33 99 117 138
32 -21 33 99 117 138
33 -21 33 99 117 138
34 -21 33 99 117 138
35 -21 33 99 117 138
36 -21 33 99 117 138
37 -21 33 99 117 138
38 -21 33 99 117 138
39 -21 33 99 117 138
40 -21 33 99 117 138
41 -21 33 99 117 138
42 -21 33 99 117 138
19 -20 33 99 117 138
20 -20 33 99 117 138
21 -20 33 99 117 138
22 -20 33 99 117 138
23 -20 33 99 117 138
24 -20 33 99 117 138
25 -20 33 99 117 138
26 -20 33 99 117 138
27 -20 33 99 117 138
28 -20 33 99 117 138
29 -20 33 99 117 138
30 -20 33 99 117 138
31 -20 33 99 117 138
32 -20 33 99 117 138
33 -20 33 99 117 138
34 -20 33 99 117 138
35 -20 33 99 117 138
36 -20 33 99 117 138
37 -20 33 99 117 138
38 -20 33 99 117 138
39 -20 33 99 117 138
40 -20 33 99 117 138
41 -20 33 99 117 138
42 -20 33 99 117 138
19 -19 33 99 117 138
20 -19 33 99 117 138
21 -19 33 99 117 138
22 -19 33 99 117 138
23 -19 33 99 117 138
24 -19 33 99 117 138
25 -19 33 99 117 138
26 -19 33 99 117 138
27 -19 33 99 117 138
28 -19 33 99 117 138
29 -19 33 99 117 138
30 -19 33 99 117 138
31 -19 33 99 117 138
32 -19 33 99 117 138
33 -19 33 99 117 138
34 -19 33 99 117 138
35 -19 33 99 117 138
36 -19 33 99 117 138
37 -19 33 99 117 138
38 -19 33 99 117 138
39 -19 33 99 117 138
40 -19 33 99 117 138
41 -19 33 99 117 138
42 -19 33 99 117 138
19 -18 33 99 117 138
20 -18 33 99 117 138
21 -18 33 99 117 138
22 -18 33 99 117 138
23 -18 33 99 117 138
24 -18 33 99 117 138
25 -18 33 99 117 138
26 -18 33 99 117 138
27 -18 33 99 117 138
28 -18 33 99 117 138
29 -18 33 99 117 138
30 -18 33 99 117 138
31 -18 33 99 117 138
32 -18 33 99 117 138
33 -18 33 99 117 138
34 -18 33 99 117 138
35 -18 33 99 117 138
36 -18 33 99 117 138
37 -18 33 99 117 138
38 -18 33 99 117 138
39 -18 33 99 117 138
40 -18 33 99 117 138
41 -18 33 99 117 138
42 -18 33 99 117 138
19 -17 33 99 117 138
20 -17 33 99 117 138
21 -17 33 99 117 138
22 -17 33 99 117 138
23 -17 33 99 117 138
24 -17 33 99 117 138
25 -17 33 99 117 138
26 -17 33 99 117 138
27 -17 33 99 117 138
28 -17 33 99 117 138
29 -17 33 99 117 138
30 -17 33 99 117 138
31 -17 33 99 117 138
32 -17 33 99 117 138
33 -17 33 99 117 138
34 -17 33 99 117 138
35 -17 33 99 117 138
36 -17 33 99 117 138
37 -17 33 99 117 138
38 -17 33 99 117 138
39 -17 33 99 117 138
40 -17 33 99 117 138
41 -17 33 99 117 138
42 -17 33 99 117 138
19 -16 33 99 117 138
20 -16 33 99 117 138
21 -16 33 99 117 138
22 -16 33 99 117 138
23 -16 33 99 117 138
24 -16 33 99 117 138
25 -16 33 99 117 138
26 -16 33 99 117 138
27 -16 33 99 117 138
28 -16 33 99 117 138
29 -16 33 99 117 138
30 -16 33 99 117 138
31 -16 33 99 117 138
32 -16 33 99 117 138
33 -16 33 99 117 138
34 -16 33 99 117 138
35 -16 33 99 117 138
36 -16 33 99 117 138
37 -16 33 99 117 138
38 -16 33 99 117 138
39 -16 33 99 117 138
40 -16 33 99 117 138
41 -16 33 99 117 138
42 -16 33 99 117 138
19 -15 33 99 117 138
20 -15 33 99 117 138
21 -15 33 99 117 138
22 -15 33 99 117 138
23 -15 33 99 117 138
24 -15 33 99 117 138
25 -15 33 99 117 138
26 -15 33 99 117 138
27 -15 33 99 117 138
28 -15 33 99 117 138
29 -15 33 99 117 138
30 -15 33 99 117 138
31 -15 33 99 117 138
32 -15 33 99 117 138
33 -15 33 99 117 138
34 -15 33 99 117 138
35 -15 33 99 117 138
36 -15 33 99 117 138
37 -15 33 99 117 138
38 -15 33 99 117 138
39 -15 33 99 117 138
40 -15 33 99 117 138
41 -15 33 99 117 138
42 -15 33 99 117 138
19 -14 33 99 117 138
20 -14 33 99 117 138
21 -14 33 99 117 138
22 -14 33 99 117 138
23 -14 33 99 117 138
24 -14 33 99 117 138
25 -14 33 99 117 138
26 -14 33 99 117 138
27 -14 33 99 117 138
28 -14 33 99 117 138
29 -14 33 99 117 138
30 -14 33 99 117 138
31 -14 33 99 117 138
32 -14 33 99 117 138
33 -14 33 99 117 138
34 -14 33 99 117 138
35 -14 33 99 117 138
36 -14 33 99 117 138
37 -14 33 99 117 138
38 -14 33 99 117 138
39 -14 33 99 117 138
40 -14 33 99 117 138
41 -14 33 99 117 138
42 -14 33 99 117 138
19 -13 33 99 117 138
20 -13 33 99 117 138
21 -13 33 99 117 138
22 -13 33 99 117 138
23 -13 33 99 117 138
24 -13 33 99 117 138
25 -13 33 99 117 138
26 -13 33 99 117 138
27 -13 33 99 117 138
28 -13 33 99 117 138
29 -13 33 99 117 138
30 -13 33 99 117 138
31 -13 33 99 117 138
32 -13 33 99 117 138
33 -13 33 99 117 138
34 -13 33 99 117 138
35 -13 33 99 117 138
36 -13 33 99 117 138
37 -13 33 99 117 138
38 -13 33 99 117 138
39 -13 33 99 117 138
40 -13 33 99 117 138
41 -13 33 99 117 138
42 -13 33 99 117 138
19 -12 33 99 117 138
20 -12 33 99 117 138
21 -12 33 99 117 138
22 -12 33 99 117 138
23 -12 33 99 117 138
24 -12 33 99 117 138
25 -12 33 99 117 138
26 -12 33 99 117 138
27 -12 33 99 117 138
28 -12 33 99 117 138
29 -12 33 99 117 138
30 -12 33 99 117 138
31 -12 33 99 117 138
32 -12 33 99 117 138
33 -12 33 99 117 138
34 -12 33 99 117 138
35 -12 33 99 117 138
36 -12 33 99 117 138
37 -12 33 99 117 138
38 -12 33 99 117 138
39 -12 33 99 117 138
40 -12 33 99 117 138
41 -12 33 99 117 138
42 -12 33 99 117 138
19 -11 33 99 117 138
20 -11 33 99 117 138
21 -11 33 99 117 138
22 -11 33 99 117 138
23 -11 33 99 117 138
24 -11 33 99 117 138
25 -11 33 99 117 138
26 -11 33 99 117 138
27 -11 33 99 117 138
28 -11 33 99 117 138
29 -11 33 99 117 138
30 -11 33 99 117 138
31 -11 33 99 117 138
32 -11 33 99 117 138
33 -11 33 99 117 138
34 -11 33 99 117 138
35 -11 33 99 117 138
36 -11 33 99 117 138
37 -11 33 99 117 138
38 -11 33 99 117 138
39 -11 33 99 117 138
40 -11 33 99 117 138
41 -11 33 99 117 138
42 -11 33 99 117 138
19 -10 33 91 108 127
20 -10 33 99 117 138
21 -10 33 99 117 138
22 -10 33 99 117 138
23 -10 33 99 117 138
24 -10 33 99 117 138
25 -10 33 99 117 138
26 -10 33 99 117 138
27 -10 33 99 117 138
28 -10 33 99 117 138
29 -10 33 99 117 138
30 -10 33 99 117 138
31 -10 33 99 117 138
32 -10 33 99 117 138
33 -10 33 99 117 138
34 -10 33 99 117 138
35 -10 33 99 117 138
36 -10 33 99 117 138
37 -10 33 99 117 138
38 -10 33 99 117 138
39 -10 33 99 117 138
40 -10 33 99 117 138
41 -10 33 99 117 138
42 -10 33 91 108 127
19 -9 33 91 108 127
20 -9 33 99 117 138
21 -9 33 99 117 138
22 -9 33 99 117 138
23 -9 33 99 117 138
24 -9 33 99 117 138
25 -9 33 99 117 138
26 -9 33 99 117 138
27 -9 33 99 117 138
28 -9 33 99 117 138
29 -9 33 99 117 138
30 -9 33 99 117 138
31 -9 33 99 117 138
32 -9 33 99 117 138
33 -9 33 99 117 138
34 -9 33 99 117 138
35 -9 33 99 117 138
36 -9 33 99 117 138
37 -9 33 99 117 138
38 -9 33 99 117 138
39 -9 33 99 117 138
40 -9 33 99 117 138
41 -9 33 99 117 138
42 -9 33 91 108 127
19 -8 33 91 108 127
20 -8 33 99 117 138
21 -8 33 99 117 138
22 -8 33 99 117 138
23 -8 33 99 117 138
24 -8 33 99 117 138
25 -8 33 99 117 138
26 -8 33 99 117 138
27 -8 33 99 117 138
28 -8 33 99 117 138
29 -8 33 99 117 138
30 -8 33 99 117 138
31 -8 33 99 117 138
32 -8 33 99 117 138
33 -8 33 99 117 138
34 -8 33 99 117 138
35 -8 33 99 117 138
36 -8 33 99 117 138
37 -8 33 99 117 138
38 -8 33 99 117 138
39 -8 33 99 117 138
40 -8 33 99 117 138
41 -8 33 99 117 138
42 -8 33 91 108 127
19 -7 33 115 136 160
20 -7 33 115 136 160
21 -7 33 115 136 160
22 -7 33 115 136 160
23 -7 33 115 136 160
24 -7 33 115 136 160
25 -7 33 115 136 160
26 -7 33 115 136 160
27 -7 33 115 136 160
28 -7 33 115 136 160
29 -7 33 115 136 160
30 -7 33 115 136 160
31 -7 33 115 136 160
32 -7 33 115 136 160
33 -7 33 115 136 160
34 -7 33 115 136 160
35 -7 33 115 136 160
36 -7 33 115 136 160
37 -7 33 115 136 160
38 -7 33 115 136 160
39 -7 33 115 136 160
40 -7 33 115 136 160
41 -7 33 115 136 160
42 -7 33 115 136 160
19 -6 33 115 136 160
42 -6 33 115 136 160
19 -5 33 115 136 160
42 -5 33 115 136 160
19 -59 34 131 154 169
20 -59 34 131 154 169
21 -59 34 131 154 169
22 -59 34 131 154 169
23 -59 34 131 154 169
24 -59 34 131 154 169
25 -59 34 131 154 169
26 -59 34 131 154 169
27 -59 34 131 154 169
28 -59 34 131 154 169
29 -59 34 131 154 169
30 -59 34 131 154 169
31 -59 34 131 154 169
32 -59 34 131 154 169
33 -59 34 131 154 169
34 -59 34 131 154 169
35 -59 34 131 154 169
36 -59 34 131 154 169
37 -59 34 131 154 169
38 -59 34 131 154 169
39 -59 34 131 154 169
40 -59 34 131 154 169
41 -59 34 131 154 169
42 -59 34 131 154 169
43 -59 34 131 154 169
44 -59 34 131 154 169
45 -59 34 131 154 169
46 -59 34 131 154 169
47 -59 34 131 154 169
48 -59 34 131 154 169
49 -59 34 131 154 169
50 -59 34 131 154 169
19 -58 34 131 154 169
20 -58 34 131 154 169
21 -58 34 131 154 169
22 -58 34 131 154 169
23 -58 34 131 154 169
24 -58 34 131 154 169
25 -58 34 131 154 169
26 -58 34 131 154 169
27 -58 34 131 154 169
28 -58 34 131 154 169
29 -58 34 131 154 169
30 -58 34 131 154 169
31 -58 34 131 154 169
32 -58 34 131 154 169
33 -58 34 131 154 169
34 -58 34 131 154 169
35 -58 34 131 154 169
36 -58 34 131 154 169
37 -58 34 131 154 169
38 -58 34 131 154 169
39 -58 34 131 154 169
40 -58 34 131 154 169
41 -58 34 131 154 169
42 -58 34 131 154 169
43 -58 34 131 154 169
44 -58 34 131 154 169
45 -58 34 131 154 169
46 -58 34 131 154 169
47 -58 34 131 154 169
48 -58 34 131 154 169
49 -58 34 131 154 169
50 -58 34 131 154 169
19 -57 34 131 154 169
20 -57 34 131 154 169
21 -57 34 131 154 169
22 -57 34 131 154 169
23 -57 34 131 154 169
24 -57 34 131 154 169
25 -57 34 131 154 169
26 -57 34 131 154 169
27 -57 34 131 154 169
28 -57 34 131 154 169
29 -57 34 131 154 169
30 -57 34 131 154 169
31 -57 34 131 154 169
32 -57 34 131 154 169
33 -57 34 131 154 169
34 -57 34 131 154 169
35 -57 34 131 154 169
36 -57 34 131 154 169
37 -57 34 131 154 169
38 -57 34 131 154 169
39 -57 34 131 154 169
40 -57 34 131 154 169
41 -57 34 131 154 169
42 -57 34 131 154 169
43 -57 34 131 154 169
44 -57 34 131 154 169
45 -57 34 131 154 169
46 -57 34 131 154 169
47 -57 34 131 154 169
48 -57 34 131 154 169
49 -57 34 131 154 169
50 -57 34 131 154 169
19 -56 34 131 154 169
20 -56 34 131 154 169
21 -56 34 131 154 169
22 -56 34 131 154 169
23 -56 34 131 154 169
24 -56 34 131 154 169
25 -56 34 131 154 169
26 -56 34 131 154 169
27 -56 34 131 154 169
28 -56 34 131 154 169
29 -56 34 131 154 169
30 -56 34 131 154 169
31 -56 34 131 154 169
32 -56 34 131 154 169
33 -56 34 131 154 169
34 -56 34 131 154 169
35 -56 34 131 154 169
36 -56 34 131 154 169
37 -56 34 131 154 169
38 -56 34 131 154 169
39 -56 34 131 154 169
40 -56 34 131 154 169
41 -56 34 131 154 169
42 -56 34 131 154 169
43 -56 34 131 154 169
44 -56 34 131 154 169
45 -56 34 131 154 169
46 -56 34 131 154 169
47 -56 34 131 154 169
48 -56 34 131 154 169
49 -56 34 131 154 169
50 -56 34 131 154 169
19 -55 34 131 154 169
20 -55 34 131 154 169
21 -55 34 131 154 169
22 -55 34 131 154 169
23 -55 34 131 154 169
24 -55 34 131 154 169
25 -55 34 131 154 169
26 -55 34 131 154 169
27 -55 34 131 154 169
28 -55 34 131 154 169
29 -55 34 131 154 169
30 -55 34 131 154 169
31 -55 34 131 154 169
32 -55 34 131 154 169
33 -55 34 131 154 169
34 -55 34 131 154 169
35 -55 34 131 154 169
36 -55 34 131 154 169
37 -55 34 131 154 169
38 -55 34 131 154 169
39 -55 34 131 154 169
40 -55 34 131 154 169
41 -55 34 131 154 169
42 -55 34 131 154 169
43 -55 34 131 154 169
44 -55 34 131 154 169
45 -55 34 131 154 169
46 -55 34 131 154 169
47 -55 34 131 154 169
48 -55 34 131 154 169
49 -55 34 131 154 169
50 -55 34 131 154 169
19 -54 34 131 154 169
20 -54 34 131 154 169
21 -54 34 131 154 169
22 -54 34 131 154 169
23 -54 34 131 154 169
24 -54 34 131 154 169
25 -54 34 131 154 169
26 -54 34 131 154 169
27 -54 34 131 154 169
28 -54 34 131 154 169
29 -54 34 131 154 169
30 -54 34 131 154 169
31 -54 34 131 154 169
32 -54 34 131 154 169
33 -54 34 131 154 169
34 -54 34 131 154 169
35 -54 34 131 154 169
36 -54 34 131 154 169
37 -54 34 131 154 169
38 -54 34 131 154 169
39 -54 34 131 154 169
40 -54 34 131 154 169
41 -54 34 131 154 169
42 -54 34 131 154 169
43 -54 34 131 154 169
44 -54 34 131 154 169
45 -54 34 131 154 169
46 -54 34 131 154 169
47 -54 34 131 154 169
48 -54 34 131 154 169
49 -54 34 131 154 169
50 -54 34 131 154 169
19 -53 34 150 176 191
20 -53 34 150 176 191
21 -53 34 150 176 191
22 -53 34 150 176 191
23 -53 34 150 176 191
24 -53 34 150 176 191
25 -53 34 150 176 191
26 -53 34 150 176 191
27 -53 34 150 176 191
28 -53 34 150 176 191
29 -53 34 150 176 191
30 -53 34 150 176 191
31 -53 34 150 176 191
32 -53 34 150 176 191
33 -53 34 150 176 191
34 -53 34 150 176 191
35 -53 34 150 176 191
36 -53 34 150 176 191
37 -53 34 150 176 191
38 -53 34 150 176 191
39 -53 34 150 176 191
40 -53 34 150 176 191
41 -53 34 150 176 191
42 -53 34 150 176 191
43 -53 34 150 176 191
44 -53 34 150 176 191
45 -53 34 150 176 191
46 -53 34 150 176 191
47 -53 34 150 176 191
48 -53 34 150 176 191
49 -53 34 150 176 191
50 -53 34 150 176 191
19 -52 34 150 176 191
20 -52 34 150 176 191
21 -52 34 150 176 191
22 -52 34 150 176 191
23 -52 34 150 176 191
24 -52 34 150 176 191
25 -52 34 150 176 191
26 -52 34 150 176 191
27 -52 34 150 176 191
28 -52 34 150 176 191
29 -52 34 150 176 191
30 -52 34 150 176 191
31 -52 34 150 176 191
32 -52 34 150 176 191
33 -52 34 150 176 191
34 -52 34 150 176 191
35 -52 34 150 176 191
36 -52 34 150 176 191
37 -52 34 150 176 191
38 -52 34 150 176 191
39 -52 34 150 176 191
40 -52 34 150 176 191
41 -52 34 150 176 191
42 -52 34 150 176 191
43 -52 34 150 176 191
44 -52 34 150 176 191
45 -52 34 150 176 191
46 -52 34 150 176 191
47 -52 34 150 176 191
48 -52 34 150 176 191
49 -52 34 150 176 191
50 -52 34 150 176 191
43 -51 34 150 176 191
44 -51 34 150 176 191
45 -51 34 150 176 191
46 -51 34 150 176 191
47 -51 34 150 176 191
48 -51 34 150 176 191
49 -51 34 150 176 191
50 -51 34 150 176 191
43 -50 34 150 176 191
44 -50 34 150 176 191
45 -50 34 150 176 191
46 -50 34 150 176 191
47 -50 34 150 176 191
48 -50 34 150 176 191
49 -50 34 150 176 191
50 -50 34 150 176 191
43 -49 34 150 176 191
44 -49 34 150 176 191
45 -49 34 150 176 191
46 -49 34 150 176 191
47 -49 34 150 176 191
48 -49 34 150 176 191
49 -49 34 150 176 191
50 -49 34 150 176 191
43 -48 34 150 176 191
44 -48 34 150 176 191
45 -48 34 150 176 191
46 -48 34 150 176 191
47 -48 34 150 176 191
48 -48 34 150 176 191
49 -48 34 150 176 191
50 -48 34 150 176 191
43 -47 34 150 176 191
44 -47 34 150 176 191
45 -47 34 150 176 191
46 -47 34 150 176 191
47 -47 34 150 176 191
48 -47 34 150 176 191
49 -47 34 150 176 191
50 -47 34 150 176 191
43 -46 34 150 176 191
44 -46 34 150 176 191
45 -46 34 150 176 191
46 -46 34 150 176 191
47 -46 34 150 176 191
48 -46 34 150 176 191
49 -46 34 150 176 191
50 -46 34 150 176 191
43 -45 34 150 176 191
44 -45 34 150 176 191
45 -45 34 150 176 191
46 -45 34 150 176 191
47 -45 34 150 176 191
48 -45 34 150 176 191
49 -45 34 150 176 191
50 -45 34 150 176 191
43 -44 34 150 176 191
44 -44 34 103 121 132
45 -44 34 150 176 191
46 -44 34 103 121 132
47 -44 34 103 121 132
48 -44 34 150 176 191
49 -44 34 103 121 132
50 -44 34 150 176 191
19 -34 34 99 117 138
20 -34 34 99 117 138
21 -34 34 99 117 138
22 -34 34 99 117 138
23 -34 34 99 117 138
24 -34 34 99 117 138
25 -34 34 99 117 138
26 -34 34 99 117 138
27 -34 34 99 117 138
28 -34 34 99 117 138
29 -34 34 99 117 138
30 -34 34 99 117 138
31 -34 34 99 117 138
32 -34 34 99 117 138
33 -34 34 99 117 138
34 -34 34 99 117 138
35 -34 34 99 117 138
36 -34 34 99 117 138
37 -34 34 99 117 138
38 -34 34 99 117 138
39 -34 34 99 117 138
40 -34 34 99 117 138
41 -34 34 99 117 138
42 -34 34 99 117 138
19 -33 34 99 117 138
20 -33 34 99 117 138
21 -33 34 99 117 138
22 -33 34 99 117 138
23 -33 34 99 117 138
24 -33 34 99 117 138
25 -33 34 99 117 138
26 -33 34 99 117 138
27 -33 34 99 117 138
28 -33 34 99 117 138
29 -33 34 99 117 138
30 -33 34 99 117 138
31 -33 34 99 117 138
32 -33 34 99 117 138
33 -33 34 99 117 138
34 -33 34 99 117 138
35 -33 34 99 117 138
36 -33 34 99 117 138
37 -33 34 99 117 138
38 -33 34 99 117 138
39 -33 34 99 117 138
40 -33 34 99 117 138
41 -33 34 99 117 138
42 -33 34 99 117 138
19 -32 34 99 117 138
20 -32 34 99 117 138
21 -32 34 99 117 138
22 -32 34 99 117 138
23 -32 34 99 117 138
24 -32 34 99 117 138
25 -32 34 99 117 138
26 -32 34 99 117 138
27 -32 34 99 117 138
28 -32 34 99 117 138
29 -32 34 99 117 138
30 -32 34 99 117 138
31 -32 34 99 117 138
32 -32 34 99 117 138
33 -32 34 99 117 138
34 -32 34 99 117 138
35 -32 34 99 117 138
36 -32 34 99 117 138
37 -32 34 99 117 138
38 -32 34 99 117 138
39 -32 34 99 117 138
40 -32 34 99 117 138
41 -32 34 99 117 138
42 -32 34 99 117 138
19 -31 34 99 117 138
20 -31 34 99 117 138
21 -31 34 99 117 138
22 -31 34 99 117 138
23 -31 34 99 117 138
24 -31 34 99 117 138
25 -31 34 99 117 138
26 -31 34 99 117 138
27 -31 34 99 117 138
28 -31 34 99 117 138
29 -31 34 99 117 138
30 -31 34 99 117 138
31 -31 34 99 117 138
32 -31 34 99 117 138
33 -31 34 99 117 138
34 -31 34 99 117 138
35 -31 34 99 117 138
36 -31 34 99 117 138
37 -31 34 99 117 138
38 -31 34 99 117 138
39 -31 34 99 117 138
40 -31 34 99 117 138
41 -31 34 99 117 138
42 -31 34 99 117 138
19 -30 34 99 117 138
20 -30 34 99 117 138
21 -30 34 99 117 138
22 -30 34 99 117 138
23 -30 34 99 117 138
24 -30 34 99 117 138
25 -30 34 99 117 138
26 -30 34 99 117 138
27 -30 34 99 117 138
28 -30 34 99 117 138
29 -30 34 99 117 138
30 -30 34 99 117 138
31 -30 34 99 117 138
32 -30 34 99 117 138
33 -30 34 99 117 138
34 -30 34 99 117 138
35 -30 34 99 117 138
36 -30 34 99 117 138
37 -30 34 99 117 138
38 -30 34 99 117 138
39 -30 34 99 117 138
40 -30 34 99 117 138
41 -30 34 99 117 138
42 -30 34 99 117 138
19 -29 34 99 117 138
20 -29 34 99 117 138
21 -29 34 99 117 138
22 -29 34 99 117 138
23 -29 34 99 117 138
24 -29 34 99 117 138
25 -29 34 99 117 138
26 -29 34 99 117 138
27 -29 34 99 117 138
28 -29 34 99 117 138
29 -29 34 99 117 138
30 -29 34 99 117 138
31 -29 34 99 117 138
32 -29 34 99 117 138
33 -29 34 99 117 138
34 -29 34 99 117 138
35 -29 34 99 117 138
36 -29 34 99 117 138
37 -29 34 99 117 138
38 -29 34 99 117 138
39 -29 34 99 117 138
40 -29 34 99 117 138
41 -29 34 99 117 138
42 -29 34 99 117 138
19 -28 34 99 117 138
20 -28 34 99 117 138
21 -28 34 99 117 138
22 -28 34 99 117 138
23 -28 34 99 117 138
24 -28 34 99 117 138
25 -28 34 99 117 138
26 -28 34 99 117 138
27 -28 34 99 117 138
28 -28 34 99 117 138
29 -28 34 99 117 138
30 -28 34 99 117 138
31 -28 34 99 117 138
32 -28 34 99 117 138
33 -28 34 99 117 138
34 -28 34 99 117 138
35 -28 34 99 117 138
36 -28 34 99 117 138
37 -28 34 99 117 138
38 -28 34 99 117 138
39 -28 34 99 117 138
40 -28 34 99 117 138
41 -28 34 99 117 138
42 -28 34 99 117 138
19 -27 34 99 117 138
20 -27 34 99 117 138
21 -27 34 99 117 138
22 -27 34 99 117 138
23 -27 34 99 117 138
24 -27 34 99 117 138
25 -27 34 99 117 138
26 -27 34 99 117 138
27 -27 34 99 117 138
28 -27 34 99 117 138
29 -27 34 99 117 138
30 -27 34 99 117 138
31 -27 34 99 117 138
32 -27 34 99 117 138
33 -27 34 99 117 138
34 -27 34 99 117 138
35 -27 34 99 117 138
36 -27 34 99 117 138
37 -27 34 99 117 138
38 -27 34 99 117 138
39 -27 34 99 117 138
40 -27 34 99 117 138
41 -27 34 99 117 138
42 -27 34 99 117 138
19 -26 34 99 117 138
20 -26 34 99 117 138
21 -26 34 99 117 138
22 -26 34 99 117 138
23 -26 34 99 117 138
24 -26 34 99 117 138
25 -26 34 99 117 138
26 -26 34 99 117 138
27 -26 34 99 117 138
28 -26 34 99 117 138
29 -26 34 99 117 138
30 -26 34 99 117 138
31 -26 34 99 117 138
32 -26 34 99 117 138
33 -26 34 99 117 138
34 -26 34 99 117 138
35 -26 34 99 117 138
36 -26 34 99 117 138
37 -26 34 99 117 138
38 -26 34 99 117 138
39 -26 34 99 117 138
40 -26 34 99 117 138
41 -26 34 99 117 138
42 -26 34 99 117 138
19 -25 34 99 117 138
20 -25 34 99 117 138
21 -25 34 99 117 138
22 -25 34 99 117 138
23 -25 34 99 117 138
24 -25 34 99 117 138
25 -25 34 99 117 138
26 -25 34 99 117 138
27 -25 34 99 117 138
28 -25 34 99 117 138
29 -25 34 99 117 138
30 -25 34 99 117 138
31 -25 34 99 117 138
32 -25 34 99 117 138
33 -25 34 99 117 138
34 -25 34 99 117 138
35 -25 34 99 117 138
36 -25 34 99 117 138
37 -25 34 99 117 138
38 -25 34 99 117 138
39 -25 34 99 117 138
40 -25 34 99 117 138
41 -25 34 99 117 138
42 -25 34 99 117 138
19 -24 34 99 117 138
20 -24 34 99 117 138
21 -24 34 99 117 138
22 -24 34 99 117 138
23 -24 34 99 117 138
24 -24 34 99 117 138
25 -24 34 99 117 138
26 -24 34 99 117 138
27 -24 34 99 117 138
28 -24 34 99 117 138
29 -24 34 99 117 138
30 -24 34 99 117 138
31 -24 34 99 117 138
32 -24 34 99 117 138
33 -24 34 99 117 138
34 -24 34 99 117 138
35 -24 34 99 117 138
36 -24 34 99 117 138
37 -24 34 99 117 138
38 -24 34 99 117 138
39 -24 34 99 117 138
40 -24 34 99 117 138
41 -24 34 99 117 138
42 -24 34 99 117 138
19 -23 34 99 117 138
20 -23 34 99 117 138
21 -23 34 99 117 138
22 -23 34 99 117 138
23 -23 34 99 117 138
24 -23 34 99 117 138
25 -23 34 99 117 138
26 -23 34 99 117 138
27 -23 34 99 117 138
28 -23 34 99 117 138
29 -23 34 99 117 138
30 -23 34 99 117 138
31 -23 34 99 117 138
32 -23 34 99 117 138
33 -23 34 99 117 138
34 -23 34 99 117 138
35 -23 34 99 117 138
36 -23 34 99 117 138
37 -23 34 99 117 138
38 -23 34 99 117 138
39 -23 34 99 117 138
40 -23 34 99 117 138
41 -23 34 99 117 138
42 -23 34 99 117 138
19 -22 34 99 117 138
20 -22 34 99 117 138
21 -22 34 99 117 138
22 -22 34 99 117 138
23 -22 34 99 117 138
24 -22 34 99 117 138
25 -22 34 99 117 138
26 -22 34 99 117 138
27 -22 34 99 117 138
28 -22 34 99 117 138
29 -22 34 99 117 138
30 -22 34 99 117 138
31 -22 34 99 117 138
32 -22 34 99 117 138
33 -22 34 99 117 138
34 -22 34 99 117 138
35 -22 34 99 117 138
36 -22 34 99 117 138
37 -22 34 99 117 138
38 -22 34 99 117 138
39 -22 34 99 117 138
40 -22 34 99 117 138
41 -22 34 99 117 138
42 -22 34 99 117 138
19 -21 34 99 117 138
20 -21 34 99 117 138
21 -21 34 99 117 138
22 -21 34 99 117 138
23 -21 34 99 117 138
24 -21 34 99 117 138
25 -21 34 99 117 138
26 -21 34 99 117 138
27 -21 34 99 117 138
28 -21 34 99 117 138
29 -21 34 99 117 138
30 -21 34 99 117 138
31 -21 34 99 117 138
32 -21 34 99 117 138
33 -21 34 99 117 138
34 -21 34 99 117 138
35 -21 34 99 117 138
36 -21 34 99 117 138
37 -21 34 99 117 138
38 -21 34 99 117 138
39 -21 34 99 117 138
40 -21 34 99 117 138
41 -21 34 99 117 138
42 -21 34 99 117 138
19 -20 34 99 117 138
20 -20 34 99 117 138
21 -20 34 99 117 138
22 -20 34 99 117 138
23 -20 34 99 117 138
24 -20 34 99 117 138
25 -20 34 99 117 138
26 -20 34 99 117 138
27 -20 34 99 117 138
28 -20 34 99 117 138
29 -20 34 99 117 138
30 -20 34 99 117 138
31 -20 34 99 117 138
32 -20 34 99 117 138
33 -20 34 99 117 138
34 -20 34 99 117 138
35 -20 34 99 117 138
36 -20 34 99 117 138
37 -20 34 99 117 138
38 -20 34 99 117 138
39 -20 34 99 117 138
40 -20 34 99 117 138
41 -20 34 99 117 138
42 -20 34 99 117 138
19 -19 34 99 117 138
20 -19 34 99 117 138
21 -19 34 99 117 138
22 -19 34 99 117 138
23 -19 34 99 117 138
24 -19 34 99 117 138
25 -19 34 99 117 138
26 -19 34 99 117 138
27 -19 34 99 117 138
28 -19 34 99 117 138
29 -19 34 99 117 138
30 -19 34 99 117 138
31 -19 34 99 117 138
32 -19 34 99 117 138
33 -19 34 99 117 138
34 -19 34 99 117 138
35 -19 34 99 117 138
36 -19 34 99 117 138
37 -19 34 99 117 138
38 -19 34 99 117 138
39 -19 34 99 117 138
40 -19 34 99 117 138
41 -19 34 99 117 138
42 -19 34 99 117 138
19 -18 34 99 117 138
20 -18 34 99 117 138
21 -18 34 99 117 138
22 -18 34 99 117 138
23 -18 34 99 117 138
24 -18 34 99 117 138
25 -18 34 99 117 138
26 -18 34 99 117 138
27 -18 34 99 117 138
28 -18 34 99 117 138
29 -18 34 99 117 138
30 -18 34 99 117 138
31 -18 34 99 117 138
32 -18 34 99 117 138
33 -18 34 99 117 138
34 -18 34 99 117 138
35 -18 34 99 117 138
36 -18 34 99 117 138
37 -18 34 99 117 138
38 -18 34 99 117 138
39 -18 34 99 117 138
40 -18 34 99 117 138
41 -18 34 99 117 138
42 -18 34 99 117 138
19 -17 34 99 117 138
20 -17 34 99 117 138
21 -17 34 99 117 138
22 -17 34 99 117 138
23 -17 34 99 117 138
24 -17 34 99 117 138
25 -17 34 99 117 138
26 -17 34 99 117 138
27 -17 34 99 117 138
28 -17 34 99 117 138
29 -17 34 99 117 138
30 -17 34 99 117 138
31 -17 34 99 117 138
32 -17 34 99 117 138
33 -17 34 99 117 138
34 -17 34 99 117 138
35 -17 34 99 117 138
36 -17 34 99 117 138
37 -17 34 99 117 138
38 -17 34 99 117 138
39 -17 34 99 117 138
40 -17 34 99 117 138
41 -17 34 99 117 138
42 -17 34 99 117 138
19 -16 34 99 117 138
20 -16 34 99 117 138
21 -16 34 99 117 138
22 -16 34 99 117 138
23 -16 34 99 117 138
24 -16 34 99 117 138
25 -16 34 99 117 138
26 -16 34 99 117 138
27 -16 34 99 117 138
28 -16 34 99 117 138
29 -16 34 99 117 138
30 -16 34 99 117 138
31 -16 34 99 117 138
32 -16 34 99 117 138
33 -16 34 99 117 138
34 -16 34 99 117 138
35 -16 34 99 117 138
36 -16 34 99 117 138
37 -16 34 99 117 138
38 -16 34 99 117 138
39 -16 34 99 117 138
40 -16 34 99 117 138
41 -16 34 99 117 138
42 -16 34 99 117 138
19 -15 34 99 117 138
20 -15 34 99 117 138
21 -15 34 99 117 138
22 -15 34 99 117 138
23 -15 34 99 117 138
24 -15 34 99 117 138
25 -15 34 99 117 138
26 -15 34 99 117 138
27 -15 34 99 117 138
28 -15 34 99 117 138
29 -15 34 99 117 138
30 -15 34 99 117 138
31 -15 34 99 117 138
32 -15 34 99 117 138
33 -15 34 99 117 138
34 -15 34 99 117 138
35 -15 34 99 117 138
36 -15 34 99 117 138
37 -15 34 99 117 138
38 -15 34 99 117 138
39 -15 34 99 117 138
40 -15 34 99 117 138
41 -15 34 99 117 138
42 -15 34 99 117 138
19 -14 34 99 117 138
20 -14 34 99 117 138
21 -14 34 99 117 138
22 -14 34 99 117 138
23 -14 34 99 117 138
24 -14 34 99 117 138
25 -14 34 99 117 138
26 -14 34 99 117 138
27 -14 34 99 117 138
28 -14 34 99 117 138
29 -14 34 99 117 138
30 -14 34 99 117 138
31 -14 34 99 117 138
32 -14 34 99 117 138
33 -14 34 99 117 138
34 -14 34 99 117 138
35 -14 34 99 117 138
36 -14 34 99 117 138
37 -14 34 99 117 138
38 -14 34 99 117 138
39 -14 34 99 117 138
40 -14 34 99 117 138
41 -14 34 99 117 138
42 -14 34 99 117 138
19 -13 34 99 117 138
20 -13 34 99 117 138
21 -13 34 99 117 138
22 -13 34 99 117 138
23 -13 34 99 117 138
24 -13 34 99 117 138
25 -13 34 99 117 138
26 -13 34 99 117 138
27 -13 34 99 117 138
28 -13 34 99 117 138
29 -13 34 99 117 138
30 -13 34 99 117 138
31 -13 34 99 117 138
32 -13 34 99 117 138
33 -13 34 99 117 138
34 -13 34 99 117 138
35 -13 34 99 117 138
36 -13 34 99 117 138
37 -13 34 99 117 138
38 -13 34 99 117 138
39 -13 34 99 117 138
40 -13 34 99 117 138
41 -13 34 99 117 138
42 -13 34 99 117 138
19 -12 34 99 117 138
20 -12 34 99 117 138
21 -12 34 99 117 138
22 -12 34 99 117 138
23 -12 34 99 117 138
24 -12 34 99 117 138
25 -12 34 99 117 138
26 -12 34 99 117 138
27 -12 34 99 117 138
28 -12 34 99 117 138
29 -12 34 99 117 138
30 -12 34 99 117 138
31 -12 34 99 117 138
32 -12 34 99 117 138
33 -12 34 99 117 138
34 -12 34 99 117 138
35 -12 34 99 117 138
36 -12 34 99 117 138
37 -12 34 99 117 138
38 -12 34 99 117 138
39 -12 34 99 117 138
40 -12 34 99 117 138
41 -12 34 99 117 138
42 -12 34 99 117 138
19 -11 34 99 117 138
20 -11 34 99 117 138
21 -11 34 99 117 138
22 -11 34 99 117 138
23 -11 34 99 117 138
24 -11 34 99 117 138
25 -11 34 99 117 138
26 -11 34 99 117 138
27 -11 34 99 117 138
28 -11 34 99 117 138
29 -11 34 99 117 138
30 -11 34 99 117 138
31 -11 34 99 117 138
32 -11 34 99 117 138
33 -11 34 99 117 138
34 -11 34 99 117 138
35 -11 34 99 117 138
36 -11 34 99 117 138
37 -11 34 99 117 138
38 -11 34 99 117 138
39 -11 34 99 117 138
40 -11 34 99 117 138
41 -11 34 99 117 138
42 -11 34 99 117 138
19 -10 34 99 117 138
20 -10 34 99 117 138
21 -10 34 99 117 138
22 -10 34 99 117 138
23 -10 34 99 117 138
24 -10 34 99 117 138
25 -10 34 99 117 138
26 -10 34 99 117 138
27 -10 34 99 117 138
28 -10 34 99 117 138
29 -10 34 99 117 138
30 -10 34 99 117 138
31 -10 34 99 117 138
32 -10 34 99 117 138
33 -10 34 99 117 138
34 -10 34 99 117 138
35 -10 34 99 117 138
36 -10 34 99 117 138
37 -10 34 99 117 138
38 -10 34 99 117 138
39 -10 34 99 117 138
40 -10 34 99 117 138
41 -10 34 99 117 138
42 -10 34 99 117 138
19 -9 34 99 117 138
20 -9 34 99 117 138
21 -9 34 99 117 138
22 -9 34 99 117 138
23 -9 34 99 117 138
24 -9 34 99 117 138
25 -9 34 99 117 138
26 -9 34 99 117 138
27 -9 34 99 117 138
28 -9 34 99 117 138
29 -9 34 99 117 138
30 -9 34 99 117 138
31 -9 34 99 117 138
32 -9 34 99 117 138
33 -9 34 99 117 138
34 -9 34 99 117 138
35 -9 34 99 117 138
36 -9 34 99 117 138
37 -9 34 99 117 138
38 -9 34 99 117 138
39 -9 34 99 117 138
40 -9 34 99 117 138
41 -9 34 99 117 138
42 -9 34 99 117 138
19 -8 34 99 117 138
20 -8 34 99 117 138
21 -8 34 99 117 138
22 -8 34 99 117 138
23 -8 34 99 117 138
24 -8 34 99 117 138
25 -8 34 99 117 138
26 -8 34 99 117 138
27 -8 34 99 117 138
28 -8 34 99 117 138
29 -8 34 99 117 138
30 -8 34 99 117 138
31 -8 34 99 117 138
32 -8 34 99 117 138
33 -8 34 99 117 138
34 -8 34 99 117 138
35 -8 34 99 117 138
36 -8 34 99 117 138
37 -8 34 99 117 138
38 -8 34 99 117 138
39 -8 34 99 117 138
40 -8 34 99 117 138
41 -8 34 99 117 138
42 -8 34 99 117 138
19 -7 34 115 136 160
20 -7 34 115 136 160
21 -7 34 115 136 160
22 -7 34 115 136 160
23 -7 34 115 136 160
24 -7 34 115 136 160
25 -7 34 115 136 160
26 -7 34 115 136 160
27 -7 34 115 136 160
28 -7 34 115 136 160
29 -7 34 115 136 160
30 -7 34 115 136 160
31 -7 34 115 136 160
32 -7 34 115 136 160
33 -7 34 115 136 160
34 -7 34 115 136 160
35 -7 34 115 136 160
36 -7 34 115 136 160
37 -7 34 115 136 160
38 -7 34 115 136 160
39 -7 34 115 136 160
40 -7 34 115 136 160
41 -7 34 115 136 160
42 -7 34 115 136 160
19 -59 35 131 154 169
20 -59 35 131 154 169
21 -59 35 131 154 169
22 -59 35 131 154 169
23 -59 35 131 154 169
24 -59 35 131 154 169
25 -59 35 131 154 169
26 -59 35 131 154 169
27 -59 35 131 154 169
28 -59 35 131 154 169
29 -59 35 131 154 169
30 -59 35 131 154 169
31 -59 35 131 154 169
32 -59 35 131 154 169
33 -59 35 131 154 169
34 -59 35 131 154 169
35 -59 35 131 154 169
36 -59 35 131 154 169
37 -59 35 131 154 169
38 -59 35 131 154 169
39 -59 35 131 154 169
40 -59 35 131 154 169
41 -59 35 131 154 169
42 -59 35 131 154 169
43 -59 35 131 154 169
44 -59 35 131 154 169
45 -59 35 131 154 169
46 -59 35 131 154 169
47 -59 35 131 154 169
48 -59 35 131 154 169
49 -59 35 131 154 169
50 -59 35 131 154 169
19 -58 35 131 154 169
20 -58 35 131 154 169
21 -58 35 131 154 169
22 -58 35 131 154 169
23 -58 35 131 154 169
24 -58 35 131 154 169
25 -58 35 131 154 169
26 -58 35 131 154 169
27 -58 35 131 154 169
28 -58 35 131 154 169
29 -58 35 131 154 169
30 -58 35 131 154 169
31 -58 35 131 154 169
32 -58 35 131 154 169
33 -58 35 131 154 169
34 -58 35 131 154 169
35 -58 35 131 154 169
36 -58 35 131 154 169
37 -58 35 131 154 169
38 -58 35 131 154 169
39 -58 35 131 154 169
40 -58 35 131 154 169
41 -58 35 131 154 169
42 -58 35 131 154 169
43 -58 35 131 154 169
44 -58 35 131 154 169
45 -58 35 131 154 169
46 -58 35 131 154 169
47 -58 35 131 154 169
48 -58 35 131 154 169
49 -58 35 131 154 169
50 -58 35 131 154 169
19 -57 35 131 154 169
20 -57 35 131 154 169
21 -57 35 131 154 169
22 -57 35 131 154 169
23 -57 35 131 154 169
24 -57 35 131 154 169
25 -57 35 131 154 169
26 -57 35 131 154 169
27 -57 35 131 154 169
28 -57 35 131 154 169
29 -57 35 131 154 169
30 -57 35 131 154 169
31 -57 35 131 154 169
32 -57 35 131 154 169
33 -57 35 131 154 169
34 -57 35 131 154 169
35 -57 35 131 154 169
36 -57 35 131 154 169
37 -57 35 131 154 169
38 -57 35 131 154 169
39 -57 35 131 154 169
40 -57 35 131 154 169
41 -57 35 131 154 169
42 -57 35 131 154 169
43 -57 35 131 154 169
44 -57 35 131 154 169
45 -57 35 131 154 169
46 -57 35 131 154 169
47 -57 35 131 154 169
48 -57 35 131 154 169
49 -57 35 131 154 169
50 -57 35 131 154 169
19 -56 35 131 154 169
20 -56 35 131 154 169
21 -56 35 131 154 169
22 -56 35 131 154 169
23 -56 35 131 154 169
24 -56 35 131 154 169
25 -56 35 131 154 169
26 -56 35 131 154 169
27 -56 35 131 154 169
28 -56 35 131 154 169
29 -56 35 131 154 169
30 -56 35 131 154 169
31 -56 35 131 154 169
32 -56 35 131 154 169
33 -56 35 131 154 169
34 -56 35 131 154 169
35 -56 35 131 154 169
36 -56 35 131 154 169
37 -56 35 131 154 169
38 -56 35 131 154 169
39 -56 35 131 154 169
40 -56 35 131 154 169
41 -56 35 131 154 169
42 -56 35 131 154 169
43 -56 35 131 154 169
44 -56 35 131 154 169
45 -56 35 131 154 169
46 -56 35 131 154 169
47 -56 35 131 154 169
48 -56 35 131 154 169
49 -56 35 131 154 169
50 -56 35 131 154 169
19 -55 35 131 154 169
20 -55 35 131 154 169
21 -55 35 131 154 169
22 -55 35 131 154 169
23 -55 35 131 154 169
24 -55 35 131 154 169
25 -55 35 131 154 169
26 -55 35 131 154 169
27 -55 35 131 154 169
28 -55 35 131 154 169
29 -55 35 131 154 169
30 -55 35 131 154 169
31 -55 35 131 154 169
32 -55 35 131 154 169
33 -55 35 131 154 169
34 -55 35 131 154 169
35 -55 35 131 154 169
36 -55 35 131 154 169
37 -55 35 131 154 169
38 -55 35 131 154 169
39 -55 35 131 154 169
40 -55 35 131 154 169
41 -55 35 131 154 169
42 -55 35 131 154 169
43 -55 35 131 154 169
44 -55 35 131 154 169
45 -55 35 131 154 169
46 -55 35 131 154 169
47 -55 35 131 154 169
48 -55 35 131 154 169
49 -55 35 131 154 169
50 -55 35 131 154 169
19 -54 35 131 154 169
20 -54 35 131 154 169
21 -54 35 131 154 169
22 -54 35 131 154 169
23 -54 35 131 154 169
24 -54 35 131 154 169
25 -54 35 131 154 169
26 -54 35 131 154 169
27 -54 35 131 154 169
28 -54 35 131 154 169
29 -54 35 131 154 169
30 -54 35 131 154 169
31 -54 35 131 154 169
32 -54 35 131 154 169
33 -54 35 131 154 169
34 -54 35 131 154 169
35 -54 35 131 154 169
36 -54 35 131 154 169
37 -54 35 131 154 169
38 -54 35 131 154 169
39 -54 35 131 154 169
40 -54 35 131 154 169
41 -54 35 131 154 169
42 -54 35 131 154 169
43 -54 35 131 154 169
44 -54 35 131 154 169
45 -54 35 131 154 169
46 -54 35 131 154 169
47 -54 35 131 154 169
48 -54 35 131 154 169
49 -54 35 131 154 169
50 -54 35 131 154 169
19 -53 35 150 176 191
20 -53 35 150 176 191
21 -53 35 150 176 191
22 -53 35 150 176 191
23 -53 35 150 176 191
24 -53 35 150 176 191
25 -53 35 150 176 191
26 -53 35 150 176 191
27 -53 35 150 176 191
28 -53 35 150 176 191
29 -53 35 150 176 191
30 -53 35 150 176 191
31 -53 35 150 176 191
32 -53 35 150 176 191
33 -53 35 150 176 191
34 -53 35 150 176 191
35 -53 35 150 176 191
36 -53 35 150 176 191
37 -53 35 150 176 191
38 -53 35 150 176 191
39 -53 35 150 176 191
40 -53 35 150 176 191
41 -53 35 150 176 191
42 -53 35 150 176 191
43 -53 35 150 176 191
44 -53 35 150 176 191
45 -53 35 150 176 191
46 -53 35 150 176 191
47 -53 35 150 176 191
48 -53 35 150 176 191
49 -53 35 150 176 191
50 -53 35 150 176 191
19 -52 35 150 176 191
20 -52 35 150 176 191
21 -52 35 150 176 191
22 -52 35 150 176 191
23 -52 35 150 176 191
24 -52 35 150 176 191
25 -52 35 150 176 191
26 -52 35 150 176 191
27 -52 35 150 176 191
28 -52 35 150 176 191
29 -52 35 150 176 191
30 -52 35 150 176 191
31 -52 35 150 176 191
32 -52 35 150 176 191
33 -52 35 150 176 191
34 -52 35 150 176 191
35 -52 35 150 176 191
36 -52 35 150 176 191
37 -52 35 150 176 191
38 -52 35 150 176 191
39 -52 35 150 176 191
40 -52 35 150 176 191
41 -52 35 150 176 191
42 -52 35 150 176 191
43 -52 35 150 176 191
44 -52 35 150 176 191
45 -52 35 150 176 191
46 -52 35 150 176 191
47 -52 35 150 176 191
48 -52 35 150 176 191
49 -52 35 150 176 191
50 -52 35 150 176 191
43 -51 35 150 176 191
44 -51 35 150 176 191
45 -51 35 150 176 191
46 -51 35 150 176 191
47 -51 35 150 176 191
48 -51 35 150 176 191
49 -51 35 150 176 191
50 -51 35 150 176 191
43 -50 35 150 176 191
44 -50 35 150 176 191
45 -50 35 150 176 191
46 -50 35 150 176 191
47 -50 35 150 176 191
48 -50 35 150 176 191
49 -50 35 150 176 191
50 -50 35 150 176 191
43 -49 35 150 176 191
44 -49 35 150 176 191
45 -49 35 150 176 191
46 -49 35 150 176 191
47 -49 35 150 176 191
48 -49 35 150 176 191
49 -49 35 150 176 191
50 -49 35 150 176 191
43 -48 35 150 176 191
44 -48 35 150 176 191
45 -48 35 150 176 191
46 -48 35 150 176 191
47 -48 35 150 176 191
48 -48 35 150 176 191
49 -48 35 150 176 191
50 -48 35 150 176 191
43 -47 35 150 176 191
44 -47 35 150 176 191
45 -47 35 150 176 191
46 -47 35 150 176 191
47 -47 35 150 176 191
48 -47 35 150 176 191
49 -47 35 150 176 191
50 -47 35 150 176 191
43 -46 35 150 176 191
44 -46 35 150 176 191
45 -46 35 150 176 191
46 -46 35 150 176 191
47 -46 35 150 176 191
48 -46 35 150 176 191
49 -46 35 150 176 191
50 -46 35 150 176 191
43 -45 35 150 176 191
44 -45 35 150 176 191
45 -45 35 150 176 191
46 -45 35 150 176 191
47 -45 35 150 176 191
48 -45 35 150 176 191
49 -45 35 150 176 191
50 -45 35 150 176 191
43 -44 35 150 176 191
44 -44 35 103 121 132
45 -44 35 150 176 191
46 -44 35 103 121 132
47 -44 35 103 121 132
48 -44 35 150 176 191
49 -44 35 103 121 132
50 -44 35 150 176 191
19 -34 35 99 117 138
20 -34 35 99 117 138
21 -34 35 99 117 138
22 -34 35 99 117 138
23 -34 35 99 117 138
24 -34 35 99 117 138
25 -34 35 99 117 138
26 -34 35 99 117 138
27 -34 35 99 117 138
28 -34 35 99 117 138
29 -34 35 99 117 138
30 -34 35 99 117 138
31 -34 35 99 117 138
32 -34 35 99 117 138
33 -34 35 99 117 138
34 -34 35 99 117 138
35 -34 35 99 117 138
36 -34 35 99 117 138
37 -34 35 99 117 138
38 -34 35 99 117 138
39 -34 35 99 117 138
40 -34 35 99 117 138
41 -34 35 99 117 138
42 -34 35 99 117 138
19 -33 35 99 117 138
20 -33 35 99 117 138
21 -33 35 99 117 138
22 -33 35 99 117 138
23 -33 35 99 117 138
24 -33 35 99 117 138
25 -33 35 99 117 138
26 -33 35 99 117 138
27 -33 35 99 117 138
28 -33 35 99 117 138
29 -33 35 99 117 138
30 -33 35 99 117 138
31 -33 35 99 117 138
32 -33 35 99 117 138
33 -33 35 99 117 138
34 -33 35 99 117 138
35 -33 35 99 117 138
36 -33 35 99 117 138
37 -33 35 99 117 138
38 -33 35 99 117 138
39 -33 35 99 117 138
40 -33 35 99 117 138
41 -33 35 99 117 138
42 -33 35 99 117 138
19 -32 35 99 117 138
20 -32 35 99 117 138
21 -32 35 99 117 138
22 -32 35 99 117 138
23 -32 35 99 117 138
24 -32 35 99 117 138
25 -32 35 99 117 138
26 -32 35 99 117 138
27 -32 35 99 117 138
28 -32 35 99 117 138
29 -32 35 99 117 138
30 -32 35 99 117 138
31 -32 35 99 117 138
32 -32 35 99 117 138
33 -32 35 99 117 138
34 -32 35 99 117 138
35 -32 35 99 117 138
36 -32 35 99 117 138
37 -32 35 99 117 138
38 -32 35 99 117 138
39 -32 35 99 117 138
40 -32 35 99 117 138
41 -32 35 99 117 138
42 -32 35 99 117 138
19 -31 35 99 117 138
20 -31 35 99 117 138
21 -31 35 99 117 138
22 -31 35 99 117 138
23 -31 35 99 117 138
24 -31 35 99 117 138
25 -31 35 99 117 138
26 -31 35 99 117 138
27 -31 35 99 117 138
28 -31 35 99 117 138
29 -31 35 99 117 138
30 -31 35 99 117 138
31 -31 35 99 117 138
32 -31 35 99 117 138
33 -31 35 99 117 138
34 -31 35 99 117 138
35 -31 35 99 117 138
36 -31 35 99 117 138
37 -31 35 99 117 138
38 -31 35 99 117 138
39 -31 35 99 117 138
40 -31 35 99 117 138
41 -31 35 99 117 138
42 -31 35 99 117 138
19 -30 35 99 117 138
20 -30 35 99 117 138
21 -30 35 99 117 138
22 -30 35 99 117 138
23 -30 35 99 117 138
24 -30 35 99 117 138
25 -30 35 99 117 138
26 -30 35 99 117 138
27 -30 35 99 117 138
28 -30 35 99 117 138
29 -30 35 99 117 138
30 -30 35 99 117 138
31 -30 35 99 117 138
32 -30 35 99 117 138
33 -30 35 99 117 138
34 -30 35 99 117 138
35 -30 35 99 117 138
36 -30 35 99 117 138
37 -30 35 99 117 138
38 -30 35 99 117 138
39 -30 35 99 117 138
40 -30 35 99 117 138
41 -30 35 99 117 138
42 -30 35 99 117 138
19 -29 35 99 117 138
20 -29 35 99 117 138
21 -29 35 99 117 138
22 -29 35 99 117 138
23 -29 35 99 117 138
24 -29 35 99 117 138
25 -29 35 99 117 138
26 -29 35 99 117 138
27 -29 35 99 117 138
28 -29 35 99 117 138
29 -29 35 99 117 138
30 -29 35 99 117 138
31 -29 35 99 117 138
32 -29 35 99 117 138
33 -29 35 99 117 138
34 -29 35 99 117 138
35 -29 35 99 117 138
36 -29 35 99 117 138
37 -29 35 99 117 138
